Workbook

Sheet PIT Data
A1: Tag | B1: SRR Code | C1: Brood Year | D1: Migration Year | E1: Hatchery Name | F1: Stock | G1: Release Site | H1: Release Site Code | I1: Mark Conditional Comment | J1: Mark Weight | K1: Mark Length | L1: SbyC | M1: Expansion | N1: Ocean Age | O1: BO1 - Bonneville Bradford Is# Ladder | P1: BO2 - Bonneville Cascades Is# Ladder | Q1: BO3 - Bonneville WA Shore Ladder/AFF | R1: BO4 - Bonneville WA Ladder Slots | S1: TD1 - The Dalles East Fish Ladder | T1: TD2 - The Dalles North Fish Ladder | U1: MC1 - McNary Oregon Shore Ladder | V1: MC2 - McNary Washington Shore Ladder | W1: ICH - Ice Harbor Dam (Combined) | X1: LMA - Lower Monumental Adult Ladders | Y1: GOA - Little Goose Fish Ladder | Z1: GRA - Lower Granite Dam Adult | AA1: Obs Year | AB1: Jack/Adult | AC1: Release Group | AD1: Above_BON_Check | AE1: boncheck | AF1: Above_TD_Check | AG1: tdcheck | AH1: Above_MCN_Check | AI1: mcncheck | AJ1: Above_ICH_Check | AK1: ichcheck | AL1: Above_lma_check | AM1: lmaCheck | AN1: Above_GOA_Check | AO1: goaCheck | AP1: granncheck | AQ1: bon_mcn_convcheck | AR1: bon_ich_convcheck | AS1: bon_lwg_convcheck | AT1: BON_MCN_TrvTime | AU1: BON_ICH_TrvTime | AV1: BON_LWG_TrvTime | AW1: BONDATEJ | AX1: TDDATEJ | AY1: MCNDATEJ | AZ1: ICHDATEJ | BA1: LMADATEJ | BB1: GOADATEJ | BC1: LWGDATEJ | BD1: 91 | BE1: =+BD1+7 -> 98 | BF1: =+BE1+7 -> 105 | BG1: =+BF1+7 -> 112 | BH1: =+BG1+7 -> 119 | BI1: =+BH1+7 -> 126 | BJ1: =+BI1+7 -> 133 | BK1: =+BJ1+7 -> 140 | BL1: =+BK1+7 -> 147 | ... BR1: =+BQ1+7 -> 189 | BS1: 3/31 adj. | BT1: 4/7 adj. | BU1: 4/14 adj. | BV1: 4/21 adj. | BW1: 4/28 adj. | BX1: 5/5 adj. | BY1: 5/12 adj. | BZ1: 5/19 adj. | CA1: 5/26 adj. | CB1: 6/2 adj. | CC1: 6/9 adj. | CD1: 6/16 adj. | CE1: 6/23 adj. | CF1: 6/30 adj. | CG1: 7/7 adj. | CJ1: Lag Period Used in Conversion Rates (days) | CK1: 20
A2: 3DD.003E33B329 | B2: 12H | C2: 2023 | D2: 2025 | E2: McCall Hatchery | F2: SF SALMON | G2: KNOXB - Knox Bridge, SF Salmon River | H2: KNOXB | I2: AI CW | L2: RTR | M2: 1 | N2: 1 | O2: 46189 | S2: 46190 | U2: 46193 | W2: 46195 | X2: 46196 | Y2: 46197 | Z2: 46198 | AA2: 2026 | AB2: Jack | AC2: McCall-Integrated | AD2: =IF(COUNT(O2:Z2)>0,1,0) -> 1 | AE2: =IF(COUNT(O2:T2)>0,1,0) -> 1 | AF2: =IF(COUNT(S2:Z2)>0,1,0) -> 1 | AG2: =IF(COUNT(S2:T2)>0,1,0) -> 1 | AH2: =IF(COUNT(U2:Z2)>0,1,0) -> 1 | AI2: =IF(COUNT(U2:V2)>0,1,0) -> 1 | AJ2: =IF(COUNT(W2:Z2)>0,1,0) -> 1 | AK2: =IF(COUNT(W2)>0,1,0) -> 1 | AL2: =IF(COUNT(X2:Z2)>0,1,0) -> 1 | AM2: =IF(COUNT(X2)>0,1,0) -> 1 | AN2: =IF(COUNT(Y2:Z2)>0,1,0) -> 1 | AO2: =IF(COUNT(Y2)>0,1,0) -> 1 | AP2: =IF(COUNT(Z2)>0,1,0) -> 1 | AQ2: =IF(AE2+AI2>1,1,0) -> 1 | AR2: =IF(AE2+AK2>1,1,0) -> 1 | AS2: =IF(AP2+AE2>1,1,0) -> 1 | AT2: =IF(AQ2=1,MIN(U2:V2)-MIN(O2:T2),"na") -> 4 | AU2: =IF(AR2=1,MAX(W2)-MIN(O2:T2),"na") -> 6 | AV2: =IF(AS2=1,+Z2-MIN(O2:T2),"na") -> 9 | AW2: =IF(AE2>0,DATE(1900,MONTH(MIN(O2:T2)),DAY(MIN(O2:T2))),"na") -> 168 | AX2: =IF(AG2>0,DATE(1900,MONTH(MIN(S2:T2)),DAY(MIN(S2:T2))),"na") -> 169 | AY2: =IF(AI2>0,DATE(1900,MONTH(MIN(U2:V2)),DAY(MIN(U2:V2))),"na") -> 172 | AZ2: =IF(AK2>0,DATE(1900,MONTH(MIN(W2)),DAY(MIN(W2))),"na") -> 174 | BA2: =IF(AM2>0,DATE(1900,MONTH(MIN(X2)),DAY(MIN(X2))),"na") -> 175 | BB2: =IF(AO2>0,DATE(1900,MONTH(MIN(Y2)),DAY(MIN(Y2))),"na") -> 176 | BC2: =IF(AP2>0,DATE(1900,MONTH(Z2),DAY(Z2)),"na") -> 177 | BD2: =IF(BD$1-$AW2>$CK$1,1,0) -> 0 | BE2: =IF(BE$1-$AW2>$CK$1,1,0) -> 0 | BF2: =IF(BF$1-$AW2>$CK$1,1,0) -> 0 | BG2: =IF(BG$1-$AW2>$CK$1,1,0) -> 0 | BH2: =IF(BH$1-$AW2>$CK$1,1,0) -> 0 | BI2: =IF(BI$1-$AW2>$CK$1,1,0) -> 0 | BJ2: =IF(BJ$1-$AW2>$CK$1,1,0) -> 0 | BK2: =IF(BK$1-$AW2>$CK$1,1,0) -> 0 | ... BR2: =IF(BR$1-$AW2>$CK$1,1,0) -> 1 | BS2: =IF(AND(BD2=1,$AP2=1),1,0) -> 0 | BT2: =IF(AND(BE2=1,$AP2=1),1,0) -> 0 | BU2: =IF(AND(BF2=1,$AP2=1),1,0) -> 0 | BV2: =IF(AND(BG2=1,$AP2=1),1,0) -> 0 | BW2: =IF(AND(BH2=1,$AP2=1),1,0) -> 0 | BX2: =IF(AND(BI2=1,$AP2=1),1,0) -> 0 | BY2: =IF(AND(BJ2=1,$AP2=1),1,0) -> 0 | BZ2: =IF(AND(BK2=1,$AP2=1),1,0) -> 0 | ... CG2: =IF(AND(BR2=1,$AP2=1),1,0) -> 1
A3: 3DD.003E543B33 | B3: 11H | C3: 2023 | D3: 2025 | E3: Rapid River Hatchery | F3: RAPID RIVER | G3: RAPH - Rapid River Hatchery | H3: RAPH | I3: AD | L3: RAL | M3: 74.25 | N3: 1 | O3: 46146 | S3: 46148 | U3: 46152 | W3: 46153 | X3: 46154 | Y3: 46156 | Z3: 46157 | AA3: 2026 | AB3: Jack | AC3: Rapid River | AD3: =IF(COUNT(O3:Z3)>0,1,0) -> 1 | AE3: =IF(COUNT(O3:T3)>0,1,0) -> 1 | AF3: =IF(COUNT(S3:Z3)>0,1,0) -> 1 | AG3: =IF(COUNT(S3:T3)>0,1,0) -> 1 | AH3: =IF(COUNT(U3:Z3)>0,1,0) -> 1 | AI3: =IF(COUNT(U3:V3)>0,1,0) -> 1 | AJ3: =IF(COUNT(W3:Z3)>0,1,0) -> 1 | AK3: =IF(COUNT(W3)>0,1,0) -> 1 | AL3: =IF(COUNT(X3:Z3)>0,1,0) -> 1 | AM3: =IF(COUNT(X3)>0,1,0) -> 1 | AN3: =IF(COUNT(Y3:Z3)>0,1,0) -> 1 | AO3: =IF(COUNT(Y3)>0,1,0) -> 1 | AP3: =IF(COUNT(Z3)>0,1,0) -> 1 | AQ3: =IF(AE3+AI3>1,1,0) -> 1 | AR3: =IF(AE3+AK3>1,1,0) -> 1 | AS3: =IF(AP3+AE3>1,1,0) -> 1 | AT3: =IF(AQ3=1,MIN(U3:V3)-MIN(O3:T3),"na") -> 6 | AU3: =IF(AR3=1,MAX(W3)-MIN(O3:T3),"na") -> 7 | AV3: =IF(AS3=1,+Z3-MIN(O3:T3),"na") -> 11 | AW3: =IF(AE3>0,DATE(1900,MONTH(MIN(O3:T3)),DAY(MIN(O3:T3))),"na") -> 125 | AX3: =IF(AG3>0,DATE(1900,MONTH(MIN(S3:T3)),DAY(MIN(S3:T3))),"na") -> 127 | AY3: =IF(AI3>0,DATE(1900,MONTH(MIN(U3:V3)),DAY(MIN(U3:V3))),"na") -> 131 | AZ3: =IF(AK3>0,DATE(1900,MONTH(MIN(W3)),DAY(MIN(W3))),"na") -> 132 | BA3: =IF(AM3>0,DATE(1900,MONTH(MIN(X3)),DAY(MIN(X3))),"na") -> 133 | BB3: =IF(AO3>0,DATE(1900,MONTH(MIN(Y3)),DAY(MIN(Y3))),"na") -> 135 | BC3: =IF(AP3>0,DATE(1900,MONTH(Z3),DAY(Z3)),"na") -> 136 | BD3: =IF(BD$1-$AW3>$CK$1,1,0) -> 0 | BE3: =IF(BE$1-$AW3>$CK$1,1,0) -> 0 | BF3: =IF(BF$1-$AW3>$CK$1,1,0) -> 0 | BG3: =IF(BG$1-$AW3>$CK$1,1,0) -> 0 | BH3: =IF(BH$1-$AW3>$CK$1,1,0) -> 0 | BI3: =IF(BI$1-$AW3>$CK$1,1,0) -> 0 | BJ3: =IF(BJ$1-$AW3>$CK$1,1,0) -> 0 | BK3: =IF(BK$1-$AW3>$CK$1,1,0) -> 0 | ... BR3: =IF(BR$1-$AW3>$CK$1,1,0) -> 1 | BS3: =IF(AND(BD3=1,$AP3=1),1,0) -> 0 | BT3: =IF(AND(BE3=1,$AP3=1),1,0) -> 0 | BU3: =IF(AND(BF3=1,$AP3=1),1,0) -> 0 | BV3: =IF(AND(BG3=1,$AP3=1),1,0) -> 0 | BW3: =IF(AND(BH3=1,$AP3=1),1,0) -> 0 | BX3: =IF(AND(BI3=1,$AP3=1),1,0) -> 0 | BY3: =IF(AND(BJ3=1,$AP3=1),1,0) -> 0 | BZ3: =IF(AND(BK3=1,$AP3=1),1,0) -> 0 | ... CG3: =IF(AND(BR3=1,$AP3=1),1,0) -> 1
A4: 3DD.003E33F82D | B4: 11H | C4: 2023 | D4: 2025 | E4: Sawtooth Hatchery | F4: SALMON R | G4: SAWT - Sawtooth Hatchery | H4: SAWT | I4: AD | L4: RTR | M4: 1 | N4: 1 | Q4: 46200 | R4: 46200 | AA4: 2026 | AB4: Jack | AC4: Sawtooth-Segregated | AD4: =IF(COUNT(O4:Z4)>0,1,0) -> 1 | AE4: =IF(COUNT(O4:T4)>0,1,0) -> 1 | AF4: =IF(COUNT(S4:Z4)>0,1,0) -> 0 | AG4: =IF(COUNT(S4:T4)>0,1,0) -> 0 | AH4: =IF(COUNT(U4:Z4)>0,1,0) -> 0 | AI4: =IF(COUNT(U4:V4)>0,1,0) -> 0 | AJ4: =IF(COUNT(W4:Z4)>0,1,0) -> 0 | AK4: =IF(COUNT(W4)>0,1,0) -> 0 | AL4: =IF(COUNT(X4:Z4)>0,1,0) -> 0 | AM4: =IF(COUNT(X4)>0,1,0) -> 0 | AN4: =IF(COUNT(Y4:Z4)>0,1,0) -> 0 | AO4: =IF(COUNT(Y4)>0,1,0) -> 0 | AP4: =IF(COUNT(Z4)>0,1,0) -> 0 | AQ4: =IF(AE4+AI4>1,1,0) -> 0 | AR4: =IF(AE4+AK4>1,1,0) -> 0 | AS4: =IF(AP4+AE4>1,1,0) -> 0 | AT4: =IF(AQ4=1,MIN(U4:V4)-MIN(O4:T4),"na") -> na | AU4: =IF(AR4=1,MAX(W4)-MIN(O4:T4),"na") -> na | AV4: =IF(AS4=1,+Z4-MIN(O4:T4),"na") -> na | AW4: =IF(AE4>0,DATE(1900,MONTH(MIN(O4:T4)),DAY(MIN(O4:T4))),"na") -> 179 | AX4: =IF(AG4>0,DATE(1900,MONTH(MIN(S4:T4)),DAY(MIN(S4:T4))),"na") -> na | AY4: =IF(AI4>0,DATE(1900,MONTH(MIN(U4:V4)),DAY(MIN(U4:V4))),"na") -> na | AZ4: =IF(AK4>0,DATE(1900,MONTH(MIN(W4)),DAY(MIN(W4))),"na") -> na | BA4: =IF(AM4>0,DATE(1900,MONTH(MIN(X4)),DAY(MIN(X4))),"na") -> na | BB4: =IF(AO4>0,DATE(1900,MONTH(MIN(Y4)),DAY(MIN(Y4))),"na") -> na | BC4: =IF(AP4>0,DATE(1900,MONTH(Z4),DAY(Z4)),"na") -> na | BD4: =IF(BD$1-$AW4>$CK$1,1,0) -> 0 | BE4: =IF(BE$1-$AW4>$CK$1,1,0) -> 0 | BF4: =IF(BF$1-$AW4>$CK$1,1,0) -> 0 | BG4: =IF(BG$1-$AW4>$CK$1,1,0) -> 0 | BH4: =IF(BH$1-$AW4>$CK$1,1,0) -> 0 | BI4: =IF(BI$1-$AW4>$CK$1,1,0) -> 0 | BJ4: =IF(BJ$1-$AW4>$CK$1,1,0) -> 0 | BK4: =IF(BK$1-$AW4>$CK$1,1,0) -> 0 | ... BR4: =IF(BR$1-$AW4>$CK$1,1,0) -> 0 | BS4: =IF(AND(BD4=1,$AP4=1),1,0) -> 0 | BT4: =IF(AND(BE4=1,$AP4=1),1,0) -> 0 | BU4: =IF(AND(BF4=1,$AP4=1),1,0) -> 0 | BV4: =IF(AND(BG4=1,$AP4=1),1,0) -> 0 | BW4: =IF(AND(BH4=1,$AP4=1),1,0) -> 0 | BX4: =IF(AND(BI4=1,$AP4=1),1,0) -> 0 | BY4: =IF(AND(BJ4=1,$AP4=1),1,0) -> 0 | BZ4: =IF(AND(BK4=1,$AP4=1),1,0) -> 0 | ... CG4: =IF(AND(BR4=1,$AP4=1),1,0) -> 0
A5: 3DD.003E33ECC7 | B5: 11H | C5: 2023 | D5: 2025 | E5: Sawtooth Hatchery | F5: SALMON R | G5: SAWT - Sawtooth Hatchery | H5: SAWT | I5: AD | L5: RAL | M5: 127.9 | N5: 1 | Q5: 46196 | R5: 46196 | T5: 46198 | U5: 46201 | AA5: 2026 | AB5: Jack | AC5: Sawtooth-Segregated | AD5: =IF(COUNT(O5:Z5)>0,1,0) -> 1 | AE5: =IF(COUNT(O5:T5)>0,1,0) -> 1 | AF5: =IF(COUNT(S5:Z5)>0,1,0) -> 1 | AG5: =IF(COUNT(S5:T5)>0,1,0) -> 1 | AH5: =IF(COUNT(U5:Z5)>0,1,0) -> 1 | AI5: =IF(COUNT(U5:V5)>0,1,0) -> 1 | AJ5: =IF(COUNT(W5:Z5)>0,1,0) -> 0 | AK5: =IF(COUNT(W5)>0,1,0) -> 0 | AL5: =IF(COUNT(X5:Z5)>0,1,0) -> 0 | AM5: =IF(COUNT(X5)>0,1,0) -> 0 | AN5: =IF(COUNT(Y5:Z5)>0,1,0) -> 0 | AO5: =IF(COUNT(Y5)>0,1,0) -> 0 | AP5: =IF(COUNT(Z5)>0,1,0) -> 0 | AQ5: =IF(AE5+AI5>1,1,0) -> 1 | AR5: =IF(AE5+AK5>1,1,0) -> 0 | AS5: =IF(AP5+AE5>1,1,0) -> 0 | AT5: =IF(AQ5=1,MIN(U5:V5)-MIN(O5:T5),"na") -> 5 | AU5: =IF(AR5=1,MAX(W5)-MIN(O5:T5),"na") -> na | AV5: =IF(AS5=1,+Z5-MIN(O5:T5),"na") -> na | AW5: =IF(AE5>0,DATE(1900,MONTH(MIN(O5:T5)),DAY(MIN(O5:T5))),"na") -> 175 | AX5: =IF(AG5>0,DATE(1900,MONTH(MIN(S5:T5)),DAY(MIN(S5:T5))),"na") -> 177 | AY5: =IF(AI5>0,DATE(1900,MONTH(MIN(U5:V5)),DAY(MIN(U5:V5))),"na") -> 180 | AZ5: =IF(AK5>0,DATE(1900,MONTH(MIN(W5)),DAY(MIN(W5))),"na") -> na | BA5: =IF(AM5>0,DATE(1900,MONTH(MIN(X5)),DAY(MIN(X5))),"na") -> na | BB5: =IF(AO5>0,DATE(1900,MONTH(MIN(Y5)),DAY(MIN(Y5))),"na") -> na | BC5: =IF(AP5>0,DATE(1900,MONTH(Z5),DAY(Z5)),"na") -> na | BD5: =IF(BD$1-$AW5>$CK$1,1,0) -> 0 | BE5: =IF(BE$1-$AW5>$CK$1,1,0) -> 0 | BF5: =IF(BF$1-$AW5>$CK$1,1,0) -> 0 | BG5: =IF(BG$1-$AW5>$CK$1,1,0) -> 0 | BH5: =IF(BH$1-$AW5>$CK$1,1,0) -> 0 | BI5: =IF(BI$1-$AW5>$CK$1,1,0) -> 0 | BJ5: =IF(BJ$1-$AW5>$CK$1,1,0) -> 0 | BK5: =IF(BK$1-$AW5>$CK$1,1,0) -> 0 | ... BR5: =IF(BR$1-$AW5>$CK$1,1,0) -> 0 | BS5: =IF(AND(BD5=1,$AP5=1),1,0) -> 0 | BT5: =IF(AND(BE5=1,$AP5=1),1,0) -> 0 | BU5: =IF(AND(BF5=1,$AP5=1),1,0) -> 0 | BV5: =IF(AND(BG5=1,$AP5=1),1,0) -> 0 | BW5: =IF(AND(BH5=1,$AP5=1),1,0) -> 0 | BX5: =IF(AND(BI5=1,$AP5=1),1,0) -> 0 | BY5: =IF(AND(BJ5=1,$AP5=1),1,0) -> 0 | BZ5: =IF(AND(BK5=1,$AP5=1),1,0) -> 0 | ... CG5: =IF(AND(BR5=1,$AP5=1),1,0) -> 0
A6: 3DD.003E33CB9C | B6: 12H | C6: 2023 | D6: 2025 | E6: McCall Hatchery | F6: SF SALMON | G6: KNOXB - Knox Bridge, SF Salmon River | H6: KNOXB | I6: AI CW | L6: RAL | M6: 7.74 | N6: 1 | Q6: 46199 | R6: 46199 | S6: 46200 | AA6: 2026 | AB6: Jack | AC6: McCall-Integrated | AD6: =IF(COUNT(O6:Z6)>0,1,0) -> 1 | AE6: =IF(COUNT(O6:T6)>0,1,0) -> 1 | AF6: =IF(COUNT(S6:Z6)>0,1,0) -> 1 | AG6: =IF(COUNT(S6:T6)>0,1,0) -> 1 | AH6: =IF(COUNT(U6:Z6)>0,1,0) -> 0 | AI6: =IF(COUNT(U6:V6)>0,1,0) -> 0 | AJ6: =IF(COUNT(W6:Z6)>0,1,0) -> 0 | AK6: =IF(COUNT(W6)>0,1,0) -> 0 | AL6: =IF(COUNT(X6:Z6)>0,1,0) -> 0 | AM6: =IF(COUNT(X6)>0,1,0) -> 0 | AN6: =IF(COUNT(Y6:Z6)>0,1,0) -> 0 | AO6: =IF(COUNT(Y6)>0,1,0) -> 0 | AP6: =IF(COUNT(Z6)>0,1,0) -> 0 | AQ6: =IF(AE6+AI6>1,1,0) -> 0 | AR6: =IF(AE6+AK6>1,1,0) -> 0 | AS6: =IF(AP6+AE6>1,1,0) -> 0 | AT6: =IF(AQ6=1,MIN(U6:V6)-MIN(O6:T6),"na") -> na | AU6: =IF(AR6=1,MAX(W6)-MIN(O6:T6),"na") -> na | AV6: =IF(AS6=1,+Z6-MIN(O6:T6),"na") -> na | AW6: =IF(AE6>0,DATE(1900,MONTH(MIN(O6:T6)),DAY(MIN(O6:T6))),"na") -> 178 | AX6: =IF(AG6>0,DATE(1900,MONTH(MIN(S6:T6)),DAY(MIN(S6:T6))),"na") -> 179 | AY6: =IF(AI6>0,DATE(1900,MONTH(MIN(U6:V6)),DAY(MIN(U6:V6))),"na") -> na | AZ6: =IF(AK6>0,DATE(1900,MONTH(MIN(W6)),DAY(MIN(W6))),"na") -> na | BA6: =IF(AM6>0,DATE(1900,MONTH(MIN(X6)),DAY(MIN(X6))),"na") -> na | BB6: =IF(AO6>0,DATE(1900,MONTH(MIN(Y6)),DAY(MIN(Y6))),"na") -> na | BC6: =IF(AP6>0,DATE(1900,MONTH(Z6),DAY(Z6)),"na") -> na | BD6: =IF(BD$1-$AW6>$CK$1,1,0) -> 0 | BE6: =IF(BE$1-$AW6>$CK$1,1,0) -> 0 | BF6: =IF(BF$1-$AW6>$CK$1,1,0) -> 0 | BG6: =IF(BG$1-$AW6>$CK$1,1,0) -> 0 | BH6: =IF(BH$1-$AW6>$CK$1,1,0) -> 0 | BI6: =IF(BI$1-$AW6>$CK$1,1,0) -> 0 | BJ6: =IF(BJ$1-$AW6>$CK$1,1,0) -> 0 | BK6: =IF(BK$1-$AW6>$CK$1,1,0) -> 0 | ... BR6: =IF(BR$1-$AW6>$CK$1,1,0) -> 0 | BS6: =IF(AND(BD6=1,$AP6=1),1,0) -> 0 | BT6: =IF(AND(BE6=1,$AP6=1),1,0) -> 0 | BU6: =IF(AND(BF6=1,$AP6=1),1,0) -> 0 | BV6: =IF(AND(BG6=1,$AP6=1),1,0) -> 0 | BW6: =IF(AND(BH6=1,$AP6=1),1,0) -> 0 | BX6: =IF(AND(BI6=1,$AP6=1),1,0) -> 0 | BY6: =IF(AND(BJ6=1,$AP6=1),1,0) -> 0 | BZ6: =IF(AND(BK6=1,$AP6=1),1,0) -> 0 | ... CG6: =IF(AND(BR6=1,$AP6=1),1,0) -> 0
A7: 3DD.003E33C823 | B7: 12H | C7: 2023 | D7: 2025 | E7: McCall Hatchery | F7: SF SALMON | G7: KNOXB - Knox Bridge, SF Salmon River | H7: KNOXB | I7: AI CW | L7: RAL | M7: 7.74 | N7: 1 | P7: 46178 | R7: 46178 | S7: 46180 | U7: 46184 | W7: 46185 | X7: 46186 | Y7: 46187 | Z7: 46188 | AA7: 2026 | AB7: Jack | AC7: McCall-Integrated | AD7: =IF(COUNT(O7:Z7)>0,1,0) -> 1 | AE7: =IF(COUNT(O7:T7)>0,1,0) -> 1 | AF7: =IF(COUNT(S7:Z7)>0,1,0) -> 1 | AG7: =IF(COUNT(S7:T7)>0,1,0) -> 1 | AH7: =IF(COUNT(U7:Z7)>0,1,0) -> 1 | AI7: =IF(COUNT(U7:V7)>0,1,0) -> 1 | AJ7: =IF(COUNT(W7:Z7)>0,1,0) -> 1 | AK7: =IF(COUNT(W7)>0,1,0) -> 1 | AL7: =IF(COUNT(X7:Z7)>0,1,0) -> 1 | AM7: =IF(COUNT(X7)>0,1,0) -> 1 | AN7: =IF(COUNT(Y7:Z7)>0,1,0) -> 1 | AO7: =IF(COUNT(Y7)>0,1,0) -> 1 | AP7: =IF(COUNT(Z7)>0,1,0) -> 1 | AQ7: =IF(AE7+AI7>1,1,0) -> 1 | AR7: =IF(AE7+AK7>1,1,0) -> 1 | AS7: =IF(AP7+AE7>1,1,0) -> 1 | AT7: =IF(AQ7=1,MIN(U7:V7)-MIN(O7:T7),"na") -> 6 | AU7: =IF(AR7=1,MAX(W7)-MIN(O7:T7),"na") -> 7 | AV7: =IF(AS7=1,+Z7-MIN(O7:T7),"na") -> 10 | AW7: =IF(AE7>0,DATE(1900,MONTH(MIN(O7:T7)),DAY(MIN(O7:T7))),"na") -> 157 | AX7: =IF(AG7>0,DATE(1900,MONTH(MIN(S7:T7)),DAY(MIN(S7:T7))),"na") -> 159 | AY7: =IF(AI7>0,DATE(1900,MONTH(MIN(U7:V7)),DAY(MIN(U7:V7))),"na") -> 163 | AZ7: =IF(AK7>0,DATE(1900,MONTH(MIN(W7)),DAY(MIN(W7))),"na") -> 164 | BA7: =IF(AM7>0,DATE(1900,MONTH(MIN(X7)),DAY(MIN(X7))),"na") -> 165 | BB7: =IF(AO7>0,DATE(1900,MONTH(MIN(Y7)),DAY(MIN(Y7))),"na") -> 166 | BC7: =IF(AP7>0,DATE(1900,MONTH(Z7),DAY(Z7)),"na") -> 167 | BD7: =IF(BD$1-$AW7>$CK$1,1,0) -> 0 | BE7: =IF(BE$1-$AW7>$CK$1,1,0) -> 0 | BF7: =IF(BF$1-$AW7>$CK$1,1,0) -> 0 | BG7: =IF(BG$1-$AW7>$CK$1,1,0) -> 0 | BH7: =IF(BH$1-$AW7>$CK$1,1,0) -> 0 | BI7: =IF(BI$1-$AW7>$CK$1,1,0) -> 0 | BJ7: =IF(BJ$1-$AW7>$CK$1,1,0) -> 0 | BK7: =IF(BK$1-$AW7>$CK$1,1,0) -> 0 | ... BR7: =IF(BR$1-$AW7>$CK$1,1,0) -> 1 | BS7: =IF(AND(BD7=1,$AP7=1),1,0) -> 0 | BT7: =IF(AND(BE7=1,$AP7=1),1,0) -> 0 | BU7: =IF(AND(BF7=1,$AP7=1),1,0) -> 0 | BV7: =IF(AND(BG7=1,$AP7=1),1,0) -> 0 | BW7: =IF(AND(BH7=1,$AP7=1),1,0) -> 0 | BX7: =IF(AND(BI7=1,$AP7=1),1,0) -> 0 | BY7: =IF(AND(BJ7=1,$AP7=1),1,0) -> 0 | BZ7: =IF(AND(BK7=1,$AP7=1),1,0) -> 0 | ... CG7: =IF(AND(BR7=1,$AP7=1),1,0) -> 1
A8: 3DD.003E349FFF | B8: 12H | C8: 2023 | D8: 2025 | E8: McCall Hatchery | F8: SF SALMON | G8: KNOXB - Knox Bridge, SF Salmon River | H8: KNOXB | I8: AD | L8: RAL | M8: 50.77 | N8: 1 | P8: 46199 | R8: 46199 | S8: 46200 | AA8: 2026 | AB8: Jack | AC8: McCall-Segregated | AD8: =IF(COUNT(O8:Z8)>0,1,0) -> 1 | AE8: =IF(COUNT(O8:T8)>0,1,0) -> 1 | AF8: =IF(COUNT(S8:Z8)>0,1,0) -> 1 | AG8: =IF(COUNT(S8:T8)>0,1,0) -> 1 | AH8: =IF(COUNT(U8:Z8)>0,1,0) -> 0 | AI8: =IF(COUNT(U8:V8)>0,1,0) -> 0 | AJ8: =IF(COUNT(W8:Z8)>0,1,0) -> 0 | AK8: =IF(COUNT(W8)>0,1,0) -> 0 | AL8: =IF(COUNT(X8:Z8)>0,1,0) -> 0 | AM8: =IF(COUNT(X8)>0,1,0) -> 0 | AN8: =IF(COUNT(Y8:Z8)>0,1,0) -> 0 | AO8: =IF(COUNT(Y8)>0,1,0) -> 0 | AP8: =IF(COUNT(Z8)>0,1,0) -> 0 | AQ8: =IF(AE8+AI8>1,1,0) -> 0 | AR8: =IF(AE8+AK8>1,1,0) -> 0 | AS8: =IF(AP8+AE8>1,1,0) -> 0 | AT8: =IF(AQ8=1,MIN(U8:V8)-MIN(O8:T8),"na") -> na | AU8: =IF(AR8=1,MAX(W8)-MIN(O8:T8),"na") -> na | AV8: =IF(AS8=1,+Z8-MIN(O8:T8),"na") -> na | AW8: =IF(AE8>0,DATE(1900,MONTH(MIN(O8:T8)),DAY(MIN(O8:T8))),"na") -> 178 | AX8: =IF(AG8>0,DATE(1900,MONTH(MIN(S8:T8)),DAY(MIN(S8:T8))),"na") -> 179 | AY8: =IF(AI8>0,DATE(1900,MONTH(MIN(U8:V8)),DAY(MIN(U8:V8))),"na") -> na | AZ8: =IF(AK8>0,DATE(1900,MONTH(MIN(W8)),DAY(MIN(W8))),"na") -> na | BA8: =IF(AM8>0,DATE(1900,MONTH(MIN(X8)),DAY(MIN(X8))),"na") -> na | BB8: =IF(AO8>0,DATE(1900,MONTH(MIN(Y8)),DAY(MIN(Y8))),"na") -> na | BC8: =IF(AP8>0,DATE(1900,MONTH(Z8),DAY(Z8)),"na") -> na | BD8: =IF(BD$1-$AW8>$CK$1,1,0) -> 0 | BE8: =IF(BE$1-$AW8>$CK$1,1,0) -> 0 | BF8: =IF(BF$1-$AW8>$CK$1,1,0) -> 0 | BG8: =IF(BG$1-$AW8>$CK$1,1,0) -> 0 | BH8: =IF(BH$1-$AW8>$CK$1,1,0) -> 0 | BI8: =IF(BI$1-$AW8>$CK$1,1,0) -> 0 | BJ8: =IF(BJ$1-$AW8>$CK$1,1,0) -> 0 | BK8: =IF(BK$1-$AW8>$CK$1,1,0) -> 0 | ... BR8: =IF(BR$1-$AW8>$CK$1,1,0) -> 0 | BS8: =IF(AND(BD8=1,$AP8=1),1,0) -> 0 | BT8: =IF(AND(BE8=1,$AP8=1),1,0) -> 0 | BU8: =IF(AND(BF8=1,$AP8=1),1,0) -> 0 | BV8: =IF(AND(BG8=1,$AP8=1),1,0) -> 0 | BW8: =IF(AND(BH8=1,$AP8=1),1,0) -> 0 | BX8: =IF(AND(BI8=1,$AP8=1),1,0) -> 0 | BY8: =IF(AND(BJ8=1,$AP8=1),1,0) -> 0 | BZ8: =IF(AND(BK8=1,$AP8=1),1,0) -> 0 | ... CG8: =IF(AND(BR8=1,$AP8=1),1,0) -> 0
A9: 3DD.003E33BAF0 | B9: 12H | C9: 2023 | D9: 2025 | E9: McCall Hatchery | F9: SF SALMON | G9: KNOXB - Knox Bridge, SF Salmon River | H9: KNOXB | I9: AI CW | L9: RTR | M9: 1 | N9: 1 | O9: 46179 | S9: 46181 | U9: 46185 | W9: 46187 | X9: 46188 | Y9: 46189 | Z9: 46190 | AA9: 2026 | AB9: Jack | AC9: McCall-Integrated | AD9: =IF(COUNT(O9:Z9)>0,1,0) -> 1 | AE9: =IF(COUNT(O9:T9)>0,1,0) -> 1 | AF9: =IF(COUNT(S9:Z9)>0,1,0) -> 1 | AG9: =IF(COUNT(S9:T9)>0,1,0) -> 1 | AH9: =IF(COUNT(U9:Z9)>0,1,0) -> 1 | AI9: =IF(COUNT(U9:V9)>0,1,0) -> 1 | AJ9: =IF(COUNT(W9:Z9)>0,1,0) -> 1 | AK9: =IF(COUNT(W9)>0,1,0) -> 1 | AL9: =IF(COUNT(X9:Z9)>0,1,0) -> 1 | AM9: =IF(COUNT(X9)>0,1,0) -> 1 | AN9: =IF(COUNT(Y9:Z9)>0,1,0) -> 1 | AO9: =IF(COUNT(Y9)>0,1,0) -> 1 | AP9: =IF(COUNT(Z9)>0,1,0) -> 1 | AQ9: =IF(AE9+AI9>1,1,0) -> 1 | AR9: =IF(AE9+AK9>1,1,0) -> 1 | AS9: =IF(AP9+AE9>1,1,0) -> 1 | AT9: =IF(AQ9=1,MIN(U9:V9)-MIN(O9:T9),"na") -> 6 | AU9: =IF(AR9=1,MAX(W9)-MIN(O9:T9),"na") -> 8 | AV9: =IF(AS9=1,+Z9-MIN(O9:T9),"na") -> 11 | AW9: =IF(AE9>0,DATE(1900,MONTH(MIN(O9:T9)),DAY(MIN(O9:T9))),"na") -> 158 | AX9: =IF(AG9>0,DATE(1900,MONTH(MIN(S9:T9)),DAY(MIN(S9:T9))),"na") -> 160 | AY9: =IF(AI9>0,DATE(1900,MONTH(MIN(U9:V9)),DAY(MIN(U9:V9))),"na") -> 164 | AZ9: =IF(AK9>0,DATE(1900,MONTH(MIN(W9)),DAY(MIN(W9))),"na") -> 166 | BA9: =IF(AM9>0,DATE(1900,MONTH(MIN(X9)),DAY(MIN(X9))),"na") -> 167 | BB9: =IF(AO9>0,DATE(1900,MONTH(MIN(Y9)),DAY(MIN(Y9))),"na") -> 168 | BC9: =IF(AP9>0,DATE(1900,MONTH(Z9),DAY(Z9)),"na") -> 169 | BD9: =IF(BD$1-$AW9>$CK$1,1,0) -> 0 | BE9: =IF(BE$1-$AW9>$CK$1,1,0) -> 0 | BF9: =IF(BF$1-$AW9>$CK$1,1,0) -> 0 | BG9: =IF(BG$1-$AW9>$CK$1,1,0) -> 0 | BH9: =IF(BH$1-$AW9>$CK$1,1,0) -> 0 | BI9: =IF(BI$1-$AW9>$CK$1,1,0) -> 0 | BJ9: =IF(BJ$1-$AW9>$CK$1,1,0) -> 0 | BK9: =IF(BK$1-$AW9>$CK$1,1,0) -> 0 | ... BR9: =IF(BR$1-$AW9>$CK$1,1,0) -> 1 | BS9: =IF(AND(BD9=1,$AP9=1),1,0) -> 0 | BT9: =IF(AND(BE9=1,$AP9=1),1,0) -> 0 | BU9: =IF(AND(BF9=1,$AP9=1),1,0) -> 0 | BV9: =IF(AND(BG9=1,$AP9=1),1,0) -> 0 | BW9: =IF(AND(BH9=1,$AP9=1),1,0) -> 0 | BX9: =IF(AND(BI9=1,$AP9=1),1,0) -> 0 | BY9: =IF(AND(BJ9=1,$AP9=1),1,0) -> 0 | BZ9: =IF(AND(BK9=1,$AP9=1),1,0) -> 0 | ... CG9: =IF(AND(BR9=1,$AP9=1),1,0) -> 1
A10: 3DD.003E34A1E7 | B10: 12H | C10: 2023 | D10: 2025 | E10: McCall Hatchery | F10: SF SALMON | G10: KNOXB - Knox Bridge, SF Salmon River | H10: KNOXB | I10: AD | L10: RAL | M10: 50.77 | N10: 1 | O10: 46161 | S10: 46162 | U10: 46165 | W10: 46168 | X10: 46169 | Y10: 46170 | Z10: 46171 | AA10: 2026 | AB10: Jack | AC10: McCall-Segregated | AD10: =IF(COUNT(O10:Z10)>0,1,0) -> 1 | AE10: =IF(COUNT(O10:T10)>0,1,0) -> 1 | AF10: =IF(COUNT(S10:Z10)>0,1,0) -> 1 | AG10: =IF(COUNT(S10:T10)>0,1,0) -> 1 | AH10: =IF(COUNT(U10:Z10)>0,1,0) -> 1 | AI10: =IF(COUNT(U10:V10)>0,1,0) -> 1 | AJ10: =IF(COUNT(W10:Z10)>0,1,0) -> 1 | AK10: =IF(COUNT(W10)>0,1,0) -> 1 | AL10: =IF(COUNT(X10:Z10)>0,1,0) -> 1 | AM10: =IF(COUNT(X10)>0,1,0) -> 1 | AN10: =IF(COUNT(Y10:Z10)>0,1,0) -> 1 | AO10: =IF(COUNT(Y10)>0,1,0) -> 1 | AP10: =IF(COUNT(Z10)>0,1,0) -> 1 | AQ10: =IF(AE10+AI10>1,1,0) -> 1 | AR10: =IF(AE10+AK10>1,1,0) -> 1 | AS10: =IF(AP10+AE10>1,1,0) -> 1 | AT10: =IF(AQ10=1,MIN(U10:V10)-MIN(O10:T10),"na") -> 4 | AU10: =IF(AR10=1,MAX(W10)-MIN(O10:T10),"na") -> 7 | AV10: =IF(AS10=1,+Z10-MIN(O10:T10),"na") -> 10 | AW10: =IF(AE10>0,DATE(1900,MONTH(MIN(O10:T10)),DAY(MIN(O10:T10))),"na") -> 140 | AX10: =IF(AG10>0,DATE(1900,MONTH(MIN(S10:T10)),DAY(MIN(S10:T10))),"na") -> 141 | AY10: =IF(AI10>0,DATE(1900,MONTH(MIN(U10:V10)),DAY(MIN(U10:V10))),"na") -> 144 | AZ10: =IF(AK10>0,DATE(1900,MONTH(MIN(W10)),DAY(MIN(W10))),"na") -> 147 | BA10: =IF(AM10>0,DATE(1900,MONTH(MIN(X10)),DAY(MIN(X10))),"na") -> 148 | BB10: =IF(AO10>0,DATE(1900,MONTH(MIN(Y10)),DAY(MIN(Y10))),"na") -> 149 | BC10: =IF(AP10>0,DATE(1900,MONTH(Z10),DAY(Z10)),"na") -> 150 | BD10: =IF(BD$1-$AW10>$CK$1,1,0) -> 0 | BE10: =IF(BE$1-$AW10>$CK$1,1,0) -> 0 | BF10: =IF(BF$1-$AW10>$CK$1,1,0) -> 0 | BG10: =IF(BG$1-$AW10>$CK$1,1,0) -> 0 | BH10: =IF(BH$1-$AW10>$CK$1,1,0) -> 0 | BI10: =IF(BI$1-$AW10>$CK$1,1,0) -> 0 | BJ10: =IF(BJ$1-$AW10>$CK$1,1,0) -> 0 | BK10: =IF(BK$1-$AW10>$CK$1,1,0) -> 0 | ... BR10: =IF(BR$1-$AW10>$CK$1,1,0) -> 1 | BS10: =IF(AND(BD10=1,$AP10=1),1,0) -> 0 | BT10: =IF(AND(BE10=1,$AP10=1),1,0) -> 0 | BU10: =IF(AND(BF10=1,$AP10=1),1,0) -> 0 | BV10: =IF(AND(BG10=1,$AP10=1),1,0) -> 0 | BW10: =IF(AND(BH10=1,$AP10=1),1,0) -> 0 | BX10: =IF(AND(BI10=1,$AP10=1),1,0) -> 0 | BY10: =IF(AND(BJ10=1,$AP10=1),1,0) -> 0 | BZ10: =IF(AND(BK10=1,$AP10=1),1,0) -> 0 | ... CG10: =IF(AND(BR10=1,$AP10=1),1,0) -> 1
A11: 3DD.003E33B097 | B11: 12H | C11: 2023 | D11: 2025 | E11: McCall Hatchery | F11: SF SALMON | G11: KNOXB - Knox Bridge, SF Salmon River | H11: KNOXB | I11: AI CW | L11: RAL | M11: 7.74 | N11: 1 | Q11: 46172 | R11: 46172 | S11: 46174 | U11: 46177 | W11: 46178 | X11: 46179 | Y11: 46180 | Z11: 46181 | AA11: 2026 | AB11: Jack | AC11: McCall-Integrated | AD11: =IF(COUNT(O11:Z11)>0,1,0) -> 1 | AE11: =IF(COUNT(O11:T11)>0,1,0) -> 1 | AF11: =IF(COUNT(S11:Z11)>0,1,0) -> 1 | AG11: =IF(COUNT(S11:T11)>0,1,0) -> 1 | AH11: =IF(COUNT(U11:Z11)>0,1,0) -> 1 | AI11: =IF(COUNT(U11:V11)>0,1,0) -> 1 | AJ11: =IF(COUNT(W11:Z11)>0,1,0) -> 1 | AK11: =IF(COUNT(W11)>0,1,0) -> 1 | AL11: =IF(COUNT(X11:Z11)>0,1,0) -> 1 | AM11: =IF(COUNT(X11)>0,1,0) -> 1 | AN11: =IF(COUNT(Y11:Z11)>0,1,0) -> 1 | AO11: =IF(COUNT(Y11)>0,1,0) -> 1 | AP11: =IF(COUNT(Z11)>0,1,0) -> 1 | AQ11: =IF(AE11+AI11>1,1,0) -> 1 | AR11: =IF(AE11+AK11>1,1,0) -> 1 | AS11: =IF(AP11+AE11>1,1,0) -> 1 | AT11: =IF(AQ11=1,MIN(U11:V11)-MIN(O11:T11),"na") -> 5 | AU11: =IF(AR11=1,MAX(W11)-MIN(O11:T11),"na") -> 6 | AV11: =IF(AS11=1,+Z11-MIN(O11:T11),"na") -> 9 | AW11: =IF(AE11>0,DATE(1900,MONTH(MIN(O11:T11)),DAY(MIN(O11:T11))),"na") -> 151 | AX11: =IF(AG11>0,DATE(1900,MONTH(MIN(S11:T11)),DAY(MIN(S11:T11))),"na") -> 153 | AY11: =IF(AI11>0,DATE(1900,MONTH(MIN(U11:V11)),DAY(MIN(U11:V11))),"na") -> 156 | AZ11: =IF(AK11>0,DATE(1900,MONTH(MIN(W11)),DAY(MIN(W11))),"na") -> 157 | BA11: =IF(AM11>0,DATE(1900,MONTH(MIN(X11)),DAY(MIN(X11))),"na") -> 158 | BB11: =IF(AO11>0,DATE(1900,MONTH(MIN(Y11)),DAY(MIN(Y11))),"na") -> 159 | BC11: =IF(AP11>0,DATE(1900,MONTH(Z11),DAY(Z11)),"na") -> 160 | BD11: =IF(BD$1-$AW11>$CK$1,1,0) -> 0 | BE11: =IF(BE$1-$AW11>$CK$1,1,0) -> 0 | BF11: =IF(BF$1-$AW11>$CK$1,1,0) -> 0 | BG11: =IF(BG$1-$AW11>$CK$1,1,0) -> 0 | BH11: =IF(BH$1-$AW11>$CK$1,1,0) -> 0 | BI11: =IF(BI$1-$AW11>$CK$1,1,0) -> 0 | BJ11: =IF(BJ$1-$AW11>$CK$1,1,0) -> 0 | BK11: =IF(BK$1-$AW11>$CK$1,1,0) -> 0 | ... BR11: =IF(BR$1-$AW11>$CK$1,1,0) -> 1 | BS11: =IF(AND(BD11=1,$AP11=1),1,0) -> 0 | BT11: =IF(AND(BE11=1,$AP11=1),1,0) -> 0 | BU11: =IF(AND(BF11=1,$AP11=1),1,0) -> 0 | BV11: =IF(AND(BG11=1,$AP11=1),1,0) -> 0 | BW11: =IF(AND(BH11=1,$AP11=1),1,0) -> 0 | BX11: =IF(AND(BI11=1,$AP11=1),1,0) -> 0 | BY11: =IF(AND(BJ11=1,$AP11=1),1,0) -> 0 | BZ11: =IF(AND(BK11=1,$AP11=1),1,0) -> 0 | ... CG11: =IF(AND(BR11=1,$AP11=1),1,0) -> 1
A12: 3DD.003E33ABE6 | B12: 12H | C12: 2023 | D12: 2025 | E12: McCall Hatchery | F12: SF SALMON | G12: KNOXB - Knox Bridge, SF Salmon River | H12: KNOXB | I12: AI CW | L12: RTR | M12: 1 | N12: 1 | R12: 46187 | AA12: 2026 | AB12: Jack | AC12: McCall-Integrated | AD12: =IF(COUNT(O12:Z12)>0,1,0) -> 1 | AE12: =IF(COUNT(O12:T12)>0,1,0) -> 1 | AF12: =IF(COUNT(S12:Z12)>0,1,0) -> 0 | AG12: =IF(COUNT(S12:T12)>0,1,0) -> 0 | AH12: =IF(COUNT(U12:Z12)>0,1,0) -> 0 | AI12: =IF(COUNT(U12:V12)>0,1,0) -> 0 | AJ12: =IF(COUNT(W12:Z12)>0,1,0) -> 0 | AK12: =IF(COUNT(W12)>0,1,0) -> 0 | AL12: =IF(COUNT(X12:Z12)>0,1,0) -> 0 | AM12: =IF(COUNT(X12)>0,1,0) -> 0 | AN12: =IF(COUNT(Y12:Z12)>0,1,0) -> 0 | AO12: =IF(COUNT(Y12)>0,1,0) -> 0 | AP12: =IF(COUNT(Z12)>0,1,0) -> 0 | AQ12: =IF(AE12+AI12>1,1,0) -> 0 | AR12: =IF(AE12+AK12>1,1,0) -> 0 | AS12: =IF(AP12+AE12>1,1,0) -> 0 | AT12: =IF(AQ12=1,MIN(U12:V12)-MIN(O12:T12),"na") -> na | AU12: =IF(AR12=1,MAX(W12)-MIN(O12:T12),"na") -> na | AV12: =IF(AS12=1,+Z12-MIN(O12:T12),"na") -> na | AW12: =IF(AE12>0,DATE(1900,MONTH(MIN(O12:T12)),DAY(MIN(O12:T12))),"na") -> 166 | AX12: =IF(AG12>0,DATE(1900,MONTH(MIN(S12:T12)),DAY(MIN(S12:T12))),"na") -> na | AY12: =IF(AI12>0,DATE(1900,MONTH(MIN(U12:V12)),DAY(MIN(U12:V12))),"na") -> na | AZ12: =IF(AK12>0,DATE(1900,MONTH(MIN(W12)),DAY(MIN(W12))),"na") -> na | BA12: =IF(AM12>0,DATE(1900,MONTH(MIN(X12)),DAY(MIN(X12))),"na") -> na | BB12: =IF(AO12>0,DATE(1900,MONTH(MIN(Y12)),DAY(MIN(Y12))),"na") -> na | BC12: =IF(AP12>0,DATE(1900,MONTH(Z12),DAY(Z12)),"na") -> na | BD12: =IF(BD$1-$AW12>$CK$1,1,0) -> 0 | BE12: =IF(BE$1-$AW12>$CK$1,1,0) -> 0 | BF12: =IF(BF$1-$AW12>$CK$1,1,0) -> 0 | BG12: =IF(BG$1-$AW12>$CK$1,1,0) -> 0 | BH12: =IF(BH$1-$AW12>$CK$1,1,0) -> 0 | BI12: =IF(BI$1-$AW12>$CK$1,1,0) -> 0 | BJ12: =IF(BJ$1-$AW12>$CK$1,1,0) -> 0 | BK12: =IF(BK$1-$AW12>$CK$1,1,0) -> 0 | ... BR12: =IF(BR$1-$AW12>$CK$1,1,0) -> 1 | BS12: =IF(AND(BD12=1,$AP12=1),1,0) -> 0 | BT12: =IF(AND(BE12=1,$AP12=1),1,0) -> 0 | BU12: =IF(AND(BF12=1,$AP12=1),1,0) -> 0 | BV12: =IF(AND(BG12=1,$AP12=1),1,0) -> 0 | BW12: =IF(AND(BH12=1,$AP12=1),1,0) -> 0 | BX12: =IF(AND(BI12=1,$AP12=1),1,0) -> 0 | BY12: =IF(AND(BJ12=1,$AP12=1),1,0) -> 0 | BZ12: =IF(AND(BK12=1,$AP12=1),1,0) -> 0 | ... CG12: =IF(AND(BR12=1,$AP12=1),1,0) -> 0
A13: 3DD.003E33A7F4 | B13: 12H | C13: 2023 | D13: 2025 | E13: McCall Hatchery | F13: SF SALMON | G13: KNOXB - Knox Bridge, SF Salmon River | H13: KNOXB | I13: AI CW | L13: RAL | M13: 7.74 | N13: 1 | O13: 46198 | S13: 46199 | AA13: 2026 | AB13: Jack | AC13: McCall-Integrated | AD13: =IF(COUNT(O13:Z13)>0,1,0) -> 1 | AE13: =IF(COUNT(O13:T13)>0,1,0) -> 1 | AF13: =IF(COUNT(S13:Z13)>0,1,0) -> 1 | AG13: =IF(COUNT(S13:T13)>0,1,0) -> 1 | AH13: =IF(COUNT(U13:Z13)>0,1,0) -> 0 | AI13: =IF(COUNT(U13:V13)>0,1,0) -> 0 | AJ13: =IF(COUNT(W13:Z13)>0,1,0) -> 0 | AK13: =IF(COUNT(W13)>0,1,0) -> 0 | AL13: =IF(COUNT(X13:Z13)>0,1,0) -> 0 | AM13: =IF(COUNT(X13)>0,1,0) -> 0 | AN13: =IF(COUNT(Y13:Z13)>0,1,0) -> 0 | AO13: =IF(COUNT(Y13)>0,1,0) -> 0 | AP13: =IF(COUNT(Z13)>0,1,0) -> 0 | AQ13: =IF(AE13+AI13>1,1,0) -> 0 | AR13: =IF(AE13+AK13>1,1,0) -> 0 | AS13: =IF(AP13+AE13>1,1,0) -> 0 | AT13: =IF(AQ13=1,MIN(U13:V13)-MIN(O13:T13),"na") -> na | AU13: =IF(AR13=1,MAX(W13)-MIN(O13:T13),"na") -> na | AV13: =IF(AS13=1,+Z13-MIN(O13:T13),"na") -> na | AW13: =IF(AE13>0,DATE(1900,MONTH(MIN(O13:T13)),DAY(MIN(O13:T13))),"na") -> 177 | AX13: =IF(AG13>0,DATE(1900,MONTH(MIN(S13:T13)),DAY(MIN(S13:T13))),"na") -> 178 | AY13: =IF(AI13>0,DATE(1900,MONTH(MIN(U13:V13)),DAY(MIN(U13:V13))),"na") -> na | AZ13: =IF(AK13>0,DATE(1900,MONTH(MIN(W13)),DAY(MIN(W13))),"na") -> na | BA13: =IF(AM13>0,DATE(1900,MONTH(MIN(X13)),DAY(MIN(X13))),"na") -> na | BB13: =IF(AO13>0,DATE(1900,MONTH(MIN(Y13)),DAY(MIN(Y13))),"na") -> na | BC13: =IF(AP13>0,DATE(1900,MONTH(Z13),DAY(Z13)),"na") -> na | BD13: =IF(BD$1-$AW13>$CK$1,1,0) -> 0 | BE13: =IF(BE$1-$AW13>$CK$1,1,0) -> 0 | BF13: =IF(BF$1-$AW13>$CK$1,1,0) -> 0 | BG13: =IF(BG$1-$AW13>$CK$1,1,0) -> 0 | BH13: =IF(BH$1-$AW13>$CK$1,1,0) -> 0 | BI13: =IF(BI$1-$AW13>$CK$1,1,0) -> 0 | BJ13: =IF(BJ$1-$AW13>$CK$1,1,0) -> 0 | BK13: =IF(BK$1-$AW13>$CK$1,1,0) -> 0 | ... BR13: =IF(BR$1-$AW13>$CK$1,1,0) -> 0 | BS13: =IF(AND(BD13=1,$AP13=1),1,0) -> 0 | BT13: =IF(AND(BE13=1,$AP13=1),1,0) -> 0 | BU13: =IF(AND(BF13=1,$AP13=1),1,0) -> 0 | BV13: =IF(AND(BG13=1,$AP13=1),1,0) -> 0 | BW13: =IF(AND(BH13=1,$AP13=1),1,0) -> 0 | BX13: =IF(AND(BI13=1,$AP13=1),1,0) -> 0 | BY13: =IF(AND(BJ13=1,$AP13=1),1,0) -> 0 | BZ13: =IF(AND(BK13=1,$AP13=1),1,0) -> 0 | ... CG13: =IF(AND(BR13=1,$AP13=1),1,0) -> 0
A14: 3DD.003E33A120 | B14: 12H | C14: 2023 | D14: 2025 | E14: McCall Hatchery | F14: SF SALMON | G14: KNOXB - Knox Bridge, SF Salmon River | H14: KNOXB | I14: AI CW | L14: RTR | M14: 1 | N14: 1 | R14: 46188 | S14: 46189 | U14: 46192 | W14: 46201 | AA14: 2026 | AB14: Jack | AC14: McCall-Integrated | AD14: =IF(COUNT(O14:Z14)>0,1,0) -> 1 | AE14: =IF(COUNT(O14:T14)>0,1,0) -> 1 | AF14: =IF(COUNT(S14:Z14)>0,1,0) -> 1 | AG14: =IF(COUNT(S14:T14)>0,1,0) -> 1 | AH14: =IF(COUNT(U14:Z14)>0,1,0) -> 1 | AI14: =IF(COUNT(U14:V14)>0,1,0) -> 1 | AJ14: =IF(COUNT(W14:Z14)>0,1,0) -> 1 | AK14: =IF(COUNT(W14)>0,1,0) -> 1 | AL14: =IF(COUNT(X14:Z14)>0,1,0) -> 0 | AM14: =IF(COUNT(X14)>0,1,0) -> 0 | AN14: =IF(COUNT(Y14:Z14)>0,1,0) -> 0 | AO14: =IF(COUNT(Y14)>0,1,0) -> 0 | AP14: =IF(COUNT(Z14)>0,1,0) -> 0 | AQ14: =IF(AE14+AI14>1,1,0) -> 1 | AR14: =IF(AE14+AK14>1,1,0) -> 1 | AS14: =IF(AP14+AE14>1,1,0) -> 0 | AT14: =IF(AQ14=1,MIN(U14:V14)-MIN(O14:T14),"na") -> 4 | AU14: =IF(AR14=1,MAX(W14)-MIN(O14:T14),"na") -> 13 | AV14: =IF(AS14=1,+Z14-MIN(O14:T14),"na") -> na | AW14: =IF(AE14>0,DATE(1900,MONTH(MIN(O14:T14)),DAY(MIN(O14:T14))),"na") -> 167 | AX14: =IF(AG14>0,DATE(1900,MONTH(MIN(S14:T14)),DAY(MIN(S14:T14))),"na") -> 168 | AY14: =IF(AI14>0,DATE(1900,MONTH(MIN(U14:V14)),DAY(MIN(U14:V14))),"na") -> 171 | AZ14: =IF(AK14>0,DATE(1900,MONTH(MIN(W14)),DAY(MIN(W14))),"na") -> 180 | BA14: =IF(AM14>0,DATE(1900,MONTH(MIN(X14)),DAY(MIN(X14))),"na") -> na | BB14: =IF(AO14>0,DATE(1900,MONTH(MIN(Y14)),DAY(MIN(Y14))),"na") -> na | BC14: =IF(AP14>0,DATE(1900,MONTH(Z14),DAY(Z14)),"na") -> na | BD14: =IF(BD$1-$AW14>$CK$1,1,0) -> 0 | BE14: =IF(BE$1-$AW14>$CK$1,1,0) -> 0 | BF14: =IF(BF$1-$AW14>$CK$1,1,0) -> 0 | BG14: =IF(BG$1-$AW14>$CK$1,1,0) -> 0 | BH14: =IF(BH$1-$AW14>$CK$1,1,0) -> 0 | BI14: =IF(BI$1-$AW14>$CK$1,1,0) -> 0 | BJ14: =IF(BJ$1-$AW14>$CK$1,1,0) -> 0 | BK14: =IF(BK$1-$AW14>$CK$1,1,0) -> 0 | ... BR14: =IF(BR$1-$AW14>$CK$1,1,0) -> 1 | BS14: =IF(AND(BD14=1,$AP14=1),1,0) -> 0 | BT14: =IF(AND(BE14=1,$AP14=1),1,0) -> 0 | BU14: =IF(AND(BF14=1,$AP14=1),1,0) -> 0 | BV14: =IF(AND(BG14=1,$AP14=1),1,0) -> 0 | BW14: =IF(AND(BH14=1,$AP14=1),1,0) -> 0 | BX14: =IF(AND(BI14=1,$AP14=1),1,0) -> 0 | BY14: =IF(AND(BJ14=1,$AP14=1),1,0) -> 0 | BZ14: =IF(AND(BK14=1,$AP14=1),1,0) -> 0 | ... CG14: =IF(AND(BR14=1,$AP14=1),1,0) -> 0
A15: 3DD.003E339E21 | B15: 12H | C15: 2023 | D15: 2025 | E15: McCall Hatchery | F15: SF SALMON | G15: KNOXB - Knox Bridge, SF Salmon River | H15: KNOXB | I15: AI CW | L15: RAL | M15: 7.74 | N15: 1 | O15: 46181 | S15: 46182 | U15: 46185 | W15: 46187 | X15: 46195 | Y15: 46197 | Z15: 46199 | AA15: 2026 | AB15: Jack | AC15: McCall-Integrated | AD15: =IF(COUNT(O15:Z15)>0,1,0) -> 1 | AE15: =IF(COUNT(O15:T15)>0,1,0) -> 1 | AF15: =IF(COUNT(S15:Z15)>0,1,0) -> 1 | AG15: =IF(COUNT(S15:T15)>0,1,0) -> 1 | AH15: =IF(COUNT(U15:Z15)>0,1,0) -> 1 | AI15: =IF(COUNT(U15:V15)>0,1,0) -> 1 | AJ15: =IF(COUNT(W15:Z15)>0,1,0) -> 1 | AK15: =IF(COUNT(W15)>0,1,0) -> 1 | AL15: =IF(COUNT(X15:Z15)>0,1,0) -> 1 | AM15: =IF(COUNT(X15)>0,1,0) -> 1 | AN15: =IF(COUNT(Y15:Z15)>0,1,0) -> 1 | AO15: =IF(COUNT(Y15)>0,1,0) -> 1 | AP15: =IF(COUNT(Z15)>0,1,0) -> 1 | AQ15: =IF(AE15+AI15>1,1,0) -> 1 | AR15: =IF(AE15+AK15>1,1,0) -> 1 | AS15: =IF(AP15+AE15>1,1,0) -> 1 | AT15: =IF(AQ15=1,MIN(U15:V15)-MIN(O15:T15),"na") -> 4 | AU15: =IF(AR15=1,MAX(W15)-MIN(O15:T15),"na") -> 6 | AV15: =IF(AS15=1,+Z15-MIN(O15:T15),"na") -> 18 | AW15: =IF(AE15>0,DATE(1900,MONTH(MIN(O15:T15)),DAY(MIN(O15:T15))),"na") -> 160 | AX15: =IF(AG15>0,DATE(1900,MONTH(MIN(S15:T15)),DAY(MIN(S15:T15))),"na") -> 161 | AY15: =IF(AI15>0,DATE(1900,MONTH(MIN(U15:V15)),DAY(MIN(U15:V15))),"na") -> 164 | AZ15: =IF(AK15>0,DATE(1900,MONTH(MIN(W15)),DAY(MIN(W15))),"na") -> 166 | BA15: =IF(AM15>0,DATE(1900,MONTH(MIN(X15)),DAY(MIN(X15))),"na") -> 174 | BB15: =IF(AO15>0,DATE(1900,MONTH(MIN(Y15)),DAY(MIN(Y15))),"na") -> 176 | BC15: =IF(AP15>0,DATE(1900,MONTH(Z15),DAY(Z15)),"na") -> 178 | BD15: =IF(BD$1-$AW15>$CK$1,1,0) -> 0 | BE15: =IF(BE$1-$AW15>$CK$1,1,0) -> 0 | BF15: =IF(BF$1-$AW15>$CK$1,1,0) -> 0 | BG15: =IF(BG$1-$AW15>$CK$1,1,0) -> 0 | BH15: =IF(BH$1-$AW15>$CK$1,1,0) -> 0 | BI15: =IF(BI$1-$AW15>$CK$1,1,0) -> 0 | BJ15: =IF(BJ$1-$AW15>$CK$1,1,0) -> 0 | BK15: =IF(BK$1-$AW15>$CK$1,1,0) -> 0 | ... BR15: =IF(BR$1-$AW15>$CK$1,1,0) -> 1 | BS15: =IF(AND(BD15=1,$AP15=1),1,0) -> 0 | BT15: =IF(AND(BE15=1,$AP15=1),1,0) -> 0 | BU15: =IF(AND(BF15=1,$AP15=1),1,0) -> 0 | BV15: =IF(AND(BG15=1,$AP15=1),1,0) -> 0 | BW15: =IF(AND(BH15=1,$AP15=1),1,0) -> 0 | BX15: =IF(AND(BI15=1,$AP15=1),1,0) -> 0 | BY15: =IF(AND(BJ15=1,$AP15=1),1,0) -> 0 | BZ15: =IF(AND(BK15=1,$AP15=1),1,0) -> 0 | ... CG15: =IF(AND(BR15=1,$AP15=1),1,0) -> 1
A16: 3DD.003E339A28 | B16: 12H | C16: 2023 | D16: 2025 | E16: McCall Hatchery | F16: SF SALMON | G16: KNOXB - Knox Bridge, SF Salmon River | H16: KNOXB | I16: AD | L16: RAL | M16: 50.77 | N16: 1 | O16: 46180 | S16: 46181 | W16: 46187 | X16: 46198 | Y16: 46199 | Z16: 46200 | AA16: 2026 | AB16: Jack | AC16: McCall-Segregated | AD16: =IF(COUNT(O16:Z16)>0,1,0) -> 1 | AE16: =IF(COUNT(O16:T16)>0,1,0) -> 1 | AF16: =IF(COUNT(S16:Z16)>0,1,0) -> 1 | AG16: =IF(COUNT(S16:T16)>0,1,0) -> 1 | AH16: =IF(COUNT(U16:Z16)>0,1,0) -> 1 | AI16: =IF(COUNT(U16:V16)>0,1,0) -> 0 | AJ16: =IF(COUNT(W16:Z16)>0,1,0) -> 1 | AK16: =IF(COUNT(W16)>0,1,0) -> 1 | AL16: =IF(COUNT(X16:Z16)>0,1,0) -> 1 | AM16: =IF(COUNT(X16)>0,1,0) -> 1 | AN16: =IF(COUNT(Y16:Z16)>0,1,0) -> 1 | AO16: =IF(COUNT(Y16)>0,1,0) -> 1 | AP16: =IF(COUNT(Z16)>0,1,0) -> 1 | AQ16: =IF(AE16+AI16>1,1,0) -> 0 | AR16: =IF(AE16+AK16>1,1,0) -> 1 | AS16: =IF(AP16+AE16>1,1,0) -> 1 | AT16: =IF(AQ16=1,MIN(U16:V16)-MIN(O16:T16),"na") -> na | AU16: =IF(AR16=1,MAX(W16)-MIN(O16:T16),"na") -> 7 | AV16: =IF(AS16=1,+Z16-MIN(O16:T16),"na") -> 20 | AW16: =IF(AE16>0,DATE(1900,MONTH(MIN(O16:T16)),DAY(MIN(O16:T16))),"na") -> 159 | AX16: =IF(AG16>0,DATE(1900,MONTH(MIN(S16:T16)),DAY(MIN(S16:T16))),"na") -> 160 | AY16: =IF(AI16>0,DATE(1900,MONTH(MIN(U16:V16)),DAY(MIN(U16:V16))),"na") -> na | AZ16: =IF(AK16>0,DATE(1900,MONTH(MIN(W16)),DAY(MIN(W16))),"na") -> 166 | BA16: =IF(AM16>0,DATE(1900,MONTH(MIN(X16)),DAY(MIN(X16))),"na") -> 177 | BB16: =IF(AO16>0,DATE(1900,MONTH(MIN(Y16)),DAY(MIN(Y16))),"na") -> 178 | BC16: =IF(AP16>0,DATE(1900,MONTH(Z16),DAY(Z16)),"na") -> 179 | BD16: =IF(BD$1-$AW16>$CK$1,1,0) -> 0 | BE16: =IF(BE$1-$AW16>$CK$1,1,0) -> 0 | BF16: =IF(BF$1-$AW16>$CK$1,1,0) -> 0 | BG16: =IF(BG$1-$AW16>$CK$1,1,0) -> 0 | BH16: =IF(BH$1-$AW16>$CK$1,1,0) -> 0 | BI16: =IF(BI$1-$AW16>$CK$1,1,0) -> 0 | BJ16: =IF(BJ$1-$AW16>$CK$1,1,0) -> 0 | BK16: =IF(BK$1-$AW16>$CK$1,1,0) -> 0 | ... BR16: =IF(BR$1-$AW16>$CK$1,1,0) -> 1 | BS16: =IF(AND(BD16=1,$AP16=1),1,0) -> 0 | BT16: =IF(AND(BE16=1,$AP16=1),1,0) -> 0 | BU16: =IF(AND(BF16=1,$AP16=1),1,0) -> 0 | BV16: =IF(AND(BG16=1,$AP16=1),1,0) -> 0 | BW16: =IF(AND(BH16=1,$AP16=1),1,0) -> 0 | BX16: =IF(AND(BI16=1,$AP16=1),1,0) -> 0 | BY16: =IF(AND(BJ16=1,$AP16=1),1,0) -> 0 | BZ16: =IF(AND(BK16=1,$AP16=1),1,0) -> 0 | ... CG16: =IF(AND(BR16=1,$AP16=1),1,0) -> 1
A17: 3DD.003E33BEEB | B17: 12H | C17: 2023 | D17: 2025 | E17: McCall Hatchery | F17: SF SALMON | G17: KNOXB - Knox Bridge, SF Salmon River | H17: KNOXB | I17: AI CW | L17: RAL | M17: 7.74 | N17: 1 | Q17: 46188 | R17: 46188 | S17: 46190 | U17: 46193 | W17: 46195 | X17: 46196 | Y17: 46197 | Z17: 46198 | AA17: 2026 | AB17: Jack | AC17: McCall-Integrated | AD17: =IF(COUNT(O17:Z17)>0,1,0) -> 1 | AE17: =IF(COUNT(O17:T17)>0,1,0) -> 1 | AF17: =IF(COUNT(S17:Z17)>0,1,0) -> 1 | AG17: =IF(COUNT(S17:T17)>0,1,0) -> 1 | AH17: =IF(COUNT(U17:Z17)>0,1,0) -> 1 | AI17: =IF(COUNT(U17:V17)>0,1,0) -> 1 | AJ17: =IF(COUNT(W17:Z17)>0,1,0) -> 1 | AK17: =IF(COUNT(W17)>0,1,0) -> 1 | AL17: =IF(COUNT(X17:Z17)>0,1,0) -> 1 | AM17: =IF(COUNT(X17)>0,1,0) -> 1 | AN17: =IF(COUNT(Y17:Z17)>0,1,0) -> 1 | AO17: =IF(COUNT(Y17)>0,1,0) -> 1 | AP17: =IF(COUNT(Z17)>0,1,0) -> 1 | AQ17: =IF(AE17+AI17>1,1,0) -> 1 | AR17: =IF(AE17+AK17>1,1,0) -> 1 | AS17: =IF(AP17+AE17>1,1,0) -> 1 | AT17: =IF(AQ17=1,MIN(U17:V17)-MIN(O17:T17),"na") -> 5 | AU17: =IF(AR17=1,MAX(W17)-MIN(O17:T17),"na") -> 7 | AV17: =IF(AS17=1,+Z17-MIN(O17:T17),"na") -> 10 | AW17: =IF(AE17>0,DATE(1900,MONTH(MIN(O17:T17)),DAY(MIN(O17:T17))),"na") -> 167 | AX17: =IF(AG17>0,DATE(1900,MONTH(MIN(S17:T17)),DAY(MIN(S17:T17))),"na") -> 169 | AY17: =IF(AI17>0,DATE(1900,MONTH(MIN(U17:V17)),DAY(MIN(U17:V17))),"na") -> 172 | AZ17: =IF(AK17>0,DATE(1900,MONTH(MIN(W17)),DAY(MIN(W17))),"na") -> 174 | BA17: =IF(AM17>0,DATE(1900,MONTH(MIN(X17)),DAY(MIN(X17))),"na") -> 175 | BB17: =IF(AO17>0,DATE(1900,MONTH(MIN(Y17)),DAY(MIN(Y17))),"na") -> 176 | BC17: =IF(AP17>0,DATE(1900,MONTH(Z17),DAY(Z17)),"na") -> 177 | BD17: =IF(BD$1-$AW17>$CK$1,1,0) -> 0 | BE17: =IF(BE$1-$AW17>$CK$1,1,0) -> 0 | BF17: =IF(BF$1-$AW17>$CK$1,1,0) -> 0 | BG17: =IF(BG$1-$AW17>$CK$1,1,0) -> 0 | BH17: =IF(BH$1-$AW17>$CK$1,1,0) -> 0 | BI17: =IF(BI$1-$AW17>$CK$1,1,0) -> 0 | BJ17: =IF(BJ$1-$AW17>$CK$1,1,0) -> 0 | BK17: =IF(BK$1-$AW17>$CK$1,1,0) -> 0 | ... BR17: =IF(BR$1-$AW17>$CK$1,1,0) -> 1 | BS17: =IF(AND(BD17=1,$AP17=1),1,0) -> 0 | BT17: =IF(AND(BE17=1,$AP17=1),1,0) -> 0 | BU17: =IF(AND(BF17=1,$AP17=1),1,0) -> 0 | BV17: =IF(AND(BG17=1,$AP17=1),1,0) -> 0 | BW17: =IF(AND(BH17=1,$AP17=1),1,0) -> 0 | BX17: =IF(AND(BI17=1,$AP17=1),1,0) -> 0 | BY17: =IF(AND(BJ17=1,$AP17=1),1,0) -> 0 | BZ17: =IF(AND(BK17=1,$AP17=1),1,0) -> 0 | ... CG17: =IF(AND(BR17=1,$AP17=1),1,0) -> 1
A18: 3DD.003E413814 | B18: 11H | C18: 2023 | D18: 2025 | E18: Clearwater Hatchery | F18: CLEARWATER | G18: SELWY1 - Selway River - mouth to Moose Creek (km 0-65) | H18: SELWY1 | I18: AD | L18: RAL | M18: 62.38 | N18: 1 | Q18: 46162 | R18: 46162 | S18: 46163 | U18: 46166 | W18: 46168 | X18: 46173 | Y18: 46174 | Z18: 46175 | AA18: 2026 | AB18: Jack | AC18: CFH-Selway Ad-Clip | AD18: =IF(COUNT(O18:Z18)>0,1,0) -> 1 | AE18: =IF(COUNT(O18:T18)>0,1,0) -> 1 | AF18: =IF(COUNT(S18:Z18)>0,1,0) -> 1 | AG18: =IF(COUNT(S18:T18)>0,1,0) -> 1 | AH18: =IF(COUNT(U18:Z18)>0,1,0) -> 1 | AI18: =IF(COUNT(U18:V18)>0,1,0) -> 1 | AJ18: =IF(COUNT(W18:Z18)>0,1,0) -> 1 | AK18: =IF(COUNT(W18)>0,1,0) -> 1 | AL18: =IF(COUNT(X18:Z18)>0,1,0) -> 1 | AM18: =IF(COUNT(X18)>0,1,0) -> 1 | AN18: =IF(COUNT(Y18:Z18)>0,1,0) -> 1 | AO18: =IF(COUNT(Y18)>0,1,0) -> 1 | AP18: =IF(COUNT(Z18)>0,1,0) -> 1 | AQ18: =IF(AE18+AI18>1,1,0) -> 1 | AR18: =IF(AE18+AK18>1,1,0) -> 1 | AS18: =IF(AP18+AE18>1,1,0) -> 1 | AT18: =IF(AQ18=1,MIN(U18:V18)-MIN(O18:T18),"na") -> 4 | AU18: =IF(AR18=1,MAX(W18)-MIN(O18:T18),"na") -> 6 | AV18: =IF(AS18=1,+Z18-MIN(O18:T18),"na") -> 13 | AW18: =IF(AE18>0,DATE(1900,MONTH(MIN(O18:T18)),DAY(MIN(O18:T18))),"na") -> 141 | AX18: =IF(AG18>0,DATE(1900,MONTH(MIN(S18:T18)),DAY(MIN(S18:T18))),"na") -> 142 | AY18: =IF(AI18>0,DATE(1900,MONTH(MIN(U18:V18)),DAY(MIN(U18:V18))),"na") -> 145 | AZ18: =IF(AK18>0,DATE(1900,MONTH(MIN(W18)),DAY(MIN(W18))),"na") -> 147 | BA18: =IF(AM18>0,DATE(1900,MONTH(MIN(X18)),DAY(MIN(X18))),"na") -> 152 | BB18: =IF(AO18>0,DATE(1900,MONTH(MIN(Y18)),DAY(MIN(Y18))),"na") -> 153 | BC18: =IF(AP18>0,DATE(1900,MONTH(Z18),DAY(Z18)),"na") -> 154 | BD18: =IF(BD$1-$AW18>$CK$1,1,0) -> 0 | BE18: =IF(BE$1-$AW18>$CK$1,1,0) -> 0 | BF18: =IF(BF$1-$AW18>$CK$1,1,0) -> 0 | BG18: =IF(BG$1-$AW18>$CK$1,1,0) -> 0 | BH18: =IF(BH$1-$AW18>$CK$1,1,0) -> 0 | BI18: =IF(BI$1-$AW18>$CK$1,1,0) -> 0 | BJ18: =IF(BJ$1-$AW18>$CK$1,1,0) -> 0 | BK18: =IF(BK$1-$AW18>$CK$1,1,0) -> 0 | ... BR18: =IF(BR$1-$AW18>$CK$1,1,0) -> 1 | BS18: =IF(AND(BD18=1,$AP18=1),1,0) -> 0 | BT18: =IF(AND(BE18=1,$AP18=1),1,0) -> 0 | BU18: =IF(AND(BF18=1,$AP18=1),1,0) -> 0 | BV18: =IF(AND(BG18=1,$AP18=1),1,0) -> 0 | BW18: =IF(AND(BH18=1,$AP18=1),1,0) -> 0 | BX18: =IF(AND(BI18=1,$AP18=1),1,0) -> 0 | BY18: =IF(AND(BJ18=1,$AP18=1),1,0) -> 0 | BZ18: =IF(AND(BK18=1,$AP18=1),1,0) -> 0 | ... CG18: =IF(AND(BR18=1,$AP18=1),1,0) -> 1
A19: 3DD.003E540B33 | B19: 11H | C19: 2023 | D19: 2025 | E19: Rapid River Hatchery | F19: RAPID RIVER | G19: RAPH - Rapid River Hatchery | H19: RAPH | I19: AD | L19: RAL | M19: 74.25 | N19: 1 | Q19: 46164 | R19: 46164 | S19: 46166 | U19: 46176 | W19: 46177 | X19: 46182 | Y19: 46183 | Z19: 46184 | AA19: 2026 | AB19: Jack | AC19: Rapid River | AD19: =IF(COUNT(O19:Z19)>0,1,0) -> 1 | AE19: =IF(COUNT(O19:T19)>0,1,0) -> 1 | AF19: =IF(COUNT(S19:Z19)>0,1,0) -> 1 | AG19: =IF(COUNT(S19:T19)>0,1,0) -> 1 | AH19: =IF(COUNT(U19:Z19)>0,1,0) -> 1 | AI19: =IF(COUNT(U19:V19)>0,1,0) -> 1 | AJ19: =IF(COUNT(W19:Z19)>0,1,0) -> 1 | AK19: =IF(COUNT(W19)>0,1,0) -> 1 | AL19: =IF(COUNT(X19:Z19)>0,1,0) -> 1 | AM19: =IF(COUNT(X19)>0,1,0) -> 1 | AN19: =IF(COUNT(Y19:Z19)>0,1,0) -> 1 | AO19: =IF(COUNT(Y19)>0,1,0) -> 1 | AP19: =IF(COUNT(Z19)>0,1,0) -> 1 | AQ19: =IF(AE19+AI19>1,1,0) -> 1 | AR19: =IF(AE19+AK19>1,1,0) -> 1 | AS19: =IF(AP19+AE19>1,1,0) -> 1 | AT19: =IF(AQ19=1,MIN(U19:V19)-MIN(O19:T19),"na") -> 12 | AU19: =IF(AR19=1,MAX(W19)-MIN(O19:T19),"na") -> 13 | AV19: =IF(AS19=1,+Z19-MIN(O19:T19),"na") -> 20 | AW19: =IF(AE19>0,DATE(1900,MONTH(MIN(O19:T19)),DAY(MIN(O19:T19))),"na") -> 143 | AX19: =IF(AG19>0,DATE(1900,MONTH(MIN(S19:T19)),DAY(MIN(S19:T19))),"na") -> 145 | AY19: =IF(AI19>0,DATE(1900,MONTH(MIN(U19:V19)),DAY(MIN(U19:V19))),"na") -> 155 | AZ19: =IF(AK19>0,DATE(1900,MONTH(MIN(W19)),DAY(MIN(W19))),"na") -> 156 | BA19: =IF(AM19>0,DATE(1900,MONTH(MIN(X19)),DAY(MIN(X19))),"na") -> 161 | BB19: =IF(AO19>0,DATE(1900,MONTH(MIN(Y19)),DAY(MIN(Y19))),"na") -> 162 | BC19: =IF(AP19>0,DATE(1900,MONTH(Z19),DAY(Z19)),"na") -> 163 | BD19: =IF(BD$1-$AW19>$CK$1,1,0) -> 0 | BE19: =IF(BE$1-$AW19>$CK$1,1,0) -> 0 | BF19: =IF(BF$1-$AW19>$CK$1,1,0) -> 0 | BG19: =IF(BG$1-$AW19>$CK$1,1,0) -> 0 | BH19: =IF(BH$1-$AW19>$CK$1,1,0) -> 0 | BI19: =IF(BI$1-$AW19>$CK$1,1,0) -> 0 | BJ19: =IF(BJ$1-$AW19>$CK$1,1,0) -> 0 | BK19: =IF(BK$1-$AW19>$CK$1,1,0) -> 0 | ... BR19: =IF(BR$1-$AW19>$CK$1,1,0) -> 1 | BS19: =IF(AND(BD19=1,$AP19=1),1,0) -> 0 | BT19: =IF(AND(BE19=1,$AP19=1),1,0) -> 0 | BU19: =IF(AND(BF19=1,$AP19=1),1,0) -> 0 | BV19: =IF(AND(BG19=1,$AP19=1),1,0) -> 0 | BW19: =IF(AND(BH19=1,$AP19=1),1,0) -> 0 | BX19: =IF(AND(BI19=1,$AP19=1),1,0) -> 0 | BY19: =IF(AND(BJ19=1,$AP19=1),1,0) -> 0 | BZ19: =IF(AND(BK19=1,$AP19=1),1,0) -> 0 | ... CG19: =IF(AND(BR19=1,$AP19=1),1,0) -> 1
A20: 3DD.003E540A00 | B20: 11H | C20: 2023 | D20: 2025 | E20: Rapid River Hatchery | F20: RAPID RIVER | G20: RAPH - Rapid River Hatchery | H20: RAPH | I20: AD | L20: RTR | M20: 1 | N20: 1 | P20: 46150 | R20: 46151 | T20: 46152 | U20: 46156 | W20: 46158 | X20: 46160 | Y20: 46162 | Z20: 46163 | AA20: 2026 | AB20: Jack | AC20: Rapid River | AD20: =IF(COUNT(O20:Z20)>0,1,0) -> 1 | AE20: =IF(COUNT(O20:T20)>0,1,0) -> 1 | AF20: =IF(COUNT(S20:Z20)>0,1,0) -> 1 | AG20: =IF(COUNT(S20:T20)>0,1,0) -> 1 | AH20: =IF(COUNT(U20:Z20)>0,1,0) -> 1 | AI20: =IF(COUNT(U20:V20)>0,1,0) -> 1 | AJ20: =IF(COUNT(W20:Z20)>0,1,0) -> 1 | AK20: =IF(COUNT(W20)>0,1,0) -> 1 | AL20: =IF(COUNT(X20:Z20)>0,1,0) -> 1 | AM20: =IF(COUNT(X20)>0,1,0) -> 1 | AN20: =IF(COUNT(Y20:Z20)>0,1,0) -> 1 | AO20: =IF(COUNT(Y20)>0,1,0) -> 1 | AP20: =IF(COUNT(Z20)>0,1,0) -> 1 | AQ20: =IF(AE20+AI20>1,1,0) -> 1 | AR20: =IF(AE20+AK20>1,1,0) -> 1 | AS20: =IF(AP20+AE20>1,1,0) -> 1 | AT20: =IF(AQ20=1,MIN(U20:V20)-MIN(O20:T20),"na") -> 6 | AU20: =IF(AR20=1,MAX(W20)-MIN(O20:T20),"na") -> 8 | AV20: =IF(AS20=1,+Z20-MIN(O20:T20),"na") -> 13 | AW20: =IF(AE20>0,DATE(1900,MONTH(MIN(O20:T20)),DAY(MIN(O20:T20))),"na") -> 129 | AX20: =IF(AG20>0,DATE(1900,MONTH(MIN(S20:T20)),DAY(MIN(S20:T20))),"na") -> 131 | AY20: =IF(AI20>0,DATE(1900,MONTH(MIN(U20:V20)),DAY(MIN(U20:V20))),"na") -> 135 | AZ20: =IF(AK20>0,DATE(1900,MONTH(MIN(W20)),DAY(MIN(W20))),"na") -> 137 | BA20: =IF(AM20>0,DATE(1900,MONTH(MIN(X20)),DAY(MIN(X20))),"na") -> 139 | BB20: =IF(AO20>0,DATE(1900,MONTH(MIN(Y20)),DAY(MIN(Y20))),"na") -> 141 | BC20: =IF(AP20>0,DATE(1900,MONTH(Z20),DAY(Z20)),"na") -> 142 | BD20: =IF(BD$1-$AW20>$CK$1,1,0) -> 0 | BE20: =IF(BE$1-$AW20>$CK$1,1,0) -> 0 | BF20: =IF(BF$1-$AW20>$CK$1,1,0) -> 0 | BG20: =IF(BG$1-$AW20>$CK$1,1,0) -> 0 | BH20: =IF(BH$1-$AW20>$CK$1,1,0) -> 0 | BI20: =IF(BI$1-$AW20>$CK$1,1,0) -> 0 | BJ20: =IF(BJ$1-$AW20>$CK$1,1,0) -> 0 | BK20: =IF(BK$1-$AW20>$CK$1,1,0) -> 0 | ... BR20: =IF(BR$1-$AW20>$CK$1,1,0) -> 1 | BS20: =IF(AND(BD20=1,$AP20=1),1,0) -> 0 | BT20: =IF(AND(BE20=1,$AP20=1),1,0) -> 0 | BU20: =IF(AND(BF20=1,$AP20=1),1,0) -> 0 | BV20: =IF(AND(BG20=1,$AP20=1),1,0) -> 0 | BW20: =IF(AND(BH20=1,$AP20=1),1,0) -> 0 | BX20: =IF(AND(BI20=1,$AP20=1),1,0) -> 0 | BY20: =IF(AND(BJ20=1,$AP20=1),1,0) -> 0 | BZ20: =IF(AND(BK20=1,$AP20=1),1,0) -> 0 | ... CG20: =IF(AND(BR20=1,$AP20=1),1,0) -> 1
A21: 3DD.003E53F89E | B21: 11H | C21: 2023 | D21: 2025 | E21: Rapid River Hatchery | F21: RAPID RIVER | G21: RAPH - Rapid River Hatchery | H21: RAPH | I21: AD | L21: RAL | M21: 74.25 | N21: 1 | Q21: 46152 | R21: 46152 | S21: 46154 | U21: 46157 | W21: 46159 | X21: 46160 | Y21: 46161 | Z21: 46163 | AA21: 2026 | AB21: Jack | AC21: Rapid River | AD21: =IF(COUNT(O21:Z21)>0,1,0) -> 1 | AE21: =IF(COUNT(O21:T21)>0,1,0) -> 1 | AF21: =IF(COUNT(S21:Z21)>0,1,0) -> 1 | AG21: =IF(COUNT(S21:T21)>0,1,0) -> 1 | AH21: =IF(COUNT(U21:Z21)>0,1,0) -> 1 | AI21: =IF(COUNT(U21:V21)>0,1,0) -> 1 | AJ21: =IF(COUNT(W21:Z21)>0,1,0) -> 1 | AK21: =IF(COUNT(W21)>0,1,0) -> 1 | AL21: =IF(COUNT(X21:Z21)>0,1,0) -> 1 | AM21: =IF(COUNT(X21)>0,1,0) -> 1 | AN21: =IF(COUNT(Y21:Z21)>0,1,0) -> 1 | AO21: =IF(COUNT(Y21)>0,1,0) -> 1 | AP21: =IF(COUNT(Z21)>0,1,0) -> 1 | AQ21: =IF(AE21+AI21>1,1,0) -> 1 | AR21: =IF(AE21+AK21>1,1,0) -> 1 | AS21: =IF(AP21+AE21>1,1,0) -> 1 | AT21: =IF(AQ21=1,MIN(U21:V21)-MIN(O21:T21),"na") -> 5 | AU21: =IF(AR21=1,MAX(W21)-MIN(O21:T21),"na") -> 7 | AV21: =IF(AS21=1,+Z21-MIN(O21:T21),"na") -> 11 | AW21: =IF(AE21>0,DATE(1900,MONTH(MIN(O21:T21)),DAY(MIN(O21:T21))),"na") -> 131 | AX21: =IF(AG21>0,DATE(1900,MONTH(MIN(S21:T21)),DAY(MIN(S21:T21))),"na") -> 133 | AY21: =IF(AI21>0,DATE(1900,MONTH(MIN(U21:V21)),DAY(MIN(U21:V21))),"na") -> 136 | AZ21: =IF(AK21>0,DATE(1900,MONTH(MIN(W21)),DAY(MIN(W21))),"na") -> 138 | BA21: =IF(AM21>0,DATE(1900,MONTH(MIN(X21)),DAY(MIN(X21))),"na") -> 139 | BB21: =IF(AO21>0,DATE(1900,MONTH(MIN(Y21)),DAY(MIN(Y21))),"na") -> 140 | BC21: =IF(AP21>0,DATE(1900,MONTH(Z21),DAY(Z21)),"na") -> 142 | BD21: =IF(BD$1-$AW21>$CK$1,1,0) -> 0 | BE21: =IF(BE$1-$AW21>$CK$1,1,0) -> 0 | BF21: =IF(BF$1-$AW21>$CK$1,1,0) -> 0 | BG21: =IF(BG$1-$AW21>$CK$1,1,0) -> 0 | BH21: =IF(BH$1-$AW21>$CK$1,1,0) -> 0 | BI21: =IF(BI$1-$AW21>$CK$1,1,0) -> 0 | BJ21: =IF(BJ$1-$AW21>$CK$1,1,0) -> 0 | BK21: =IF(BK$1-$AW21>$CK$1,1,0) -> 0 | ... BR21: =IF(BR$1-$AW21>$CK$1,1,0) -> 1 | BS21: =IF(AND(BD21=1,$AP21=1),1,0) -> 0 | BT21: =IF(AND(BE21=1,$AP21=1),1,0) -> 0 | BU21: =IF(AND(BF21=1,$AP21=1),1,0) -> 0 | BV21: =IF(AND(BG21=1,$AP21=1),1,0) -> 0 | BW21: =IF(AND(BH21=1,$AP21=1),1,0) -> 0 | BX21: =IF(AND(BI21=1,$AP21=1),1,0) -> 0 | BY21: =IF(AND(BJ21=1,$AP21=1),1,0) -> 0 | BZ21: =IF(AND(BK21=1,$AP21=1),1,0) -> 0 | ... CG21: =IF(AND(BR21=1,$AP21=1),1,0) -> 1
A22: 3DD.003E53E698 | B22: 11H | C22: 2023 | D22: 2025 | E22: Rapid River Hatchery | F22: RAPID RIVER | G22: RAPH - Rapid River Hatchery | H22: RAPH | I22: AD | L22: RAL | M22: 74.25 | N22: 1 | Q22: 46184 | R22: 46184 | AA22: 2026 | AB22: Jack | AC22: Rapid River | AD22: =IF(COUNT(O22:Z22)>0,1,0) -> 1 | AE22: =IF(COUNT(O22:T22)>0,1,0) -> 1 | AF22: =IF(COUNT(S22:Z22)>0,1,0) -> 0 | AG22: =IF(COUNT(S22:T22)>0,1,0) -> 0 | AH22: =IF(COUNT(U22:Z22)>0,1,0) -> 0 | AI22: =IF(COUNT(U22:V22)>0,1,0) -> 0 | AJ22: =IF(COUNT(W22:Z22)>0,1,0) -> 0 | AK22: =IF(COUNT(W22)>0,1,0) -> 0 | AL22: =IF(COUNT(X22:Z22)>0,1,0) -> 0 | AM22: =IF(COUNT(X22)>0,1,0) -> 0 | AN22: =IF(COUNT(Y22:Z22)>0,1,0) -> 0 | AO22: =IF(COUNT(Y22)>0,1,0) -> 0 | AP22: =IF(COUNT(Z22)>0,1,0) -> 0 | AQ22: =IF(AE22+AI22>1,1,0) -> 0 | AR22: =IF(AE22+AK22>1,1,0) -> 0 | AS22: =IF(AP22+AE22>1,1,0) -> 0 | AT22: =IF(AQ22=1,MIN(U22:V22)-MIN(O22:T22),"na") -> na | AU22: =IF(AR22=1,MAX(W22)-MIN(O22:T22),"na") -> na | AV22: =IF(AS22=1,+Z22-MIN(O22:T22),"na") -> na | AW22: =IF(AE22>0,DATE(1900,MONTH(MIN(O22:T22)),DAY(MIN(O22:T22))),"na") -> 163 | AX22: =IF(AG22>0,DATE(1900,MONTH(MIN(S22:T22)),DAY(MIN(S22:T22))),"na") -> na | AY22: =IF(AI22>0,DATE(1900,MONTH(MIN(U22:V22)),DAY(MIN(U22:V22))),"na") -> na | AZ22: =IF(AK22>0,DATE(1900,MONTH(MIN(W22)),DAY(MIN(W22))),"na") -> na | BA22: =IF(AM22>0,DATE(1900,MONTH(MIN(X22)),DAY(MIN(X22))),"na") -> na | BB22: =IF(AO22>0,DATE(1900,MONTH(MIN(Y22)),DAY(MIN(Y22))),"na") -> na | BC22: =IF(AP22>0,DATE(1900,MONTH(Z22),DAY(Z22)),"na") -> na | BD22: =IF(BD$1-$AW22>$CK$1,1,0) -> 0 | BE22: =IF(BE$1-$AW22>$CK$1,1,0) -> 0 | BF22: =IF(BF$1-$AW22>$CK$1,1,0) -> 0 | BG22: =IF(BG$1-$AW22>$CK$1,1,0) -> 0 | BH22: =IF(BH$1-$AW22>$CK$1,1,0) -> 0 | BI22: =IF(BI$1-$AW22>$CK$1,1,0) -> 0 | BJ22: =IF(BJ$1-$AW22>$CK$1,1,0) -> 0 | BK22: =IF(BK$1-$AW22>$CK$1,1,0) -> 0 | ... BR22: =IF(BR$1-$AW22>$CK$1,1,0) -> 1 | BS22: =IF(AND(BD22=1,$AP22=1),1,0) -> 0 | BT22: =IF(AND(BE22=1,$AP22=1),1,0) -> 0 | BU22: =IF(AND(BF22=1,$AP22=1),1,0) -> 0 | BV22: =IF(AND(BG22=1,$AP22=1),1,0) -> 0 | BW22: =IF(AND(BH22=1,$AP22=1),1,0) -> 0 | BX22: =IF(AND(BI22=1,$AP22=1),1,0) -> 0 | BY22: =IF(AND(BJ22=1,$AP22=1),1,0) -> 0 | BZ22: =IF(AND(BK22=1,$AP22=1),1,0) -> 0 | ... CG22: =IF(AND(BR22=1,$AP22=1),1,0) -> 0
A23: 3DD.003E53E2B2 | B23: 11H | C23: 2023 | D23: 2025 | E23: Rapid River Hatchery | F23: RAPID RIVER | G23: RAPH - Rapid River Hatchery | H23: RAPH | I23: AD | L23: RTR | M23: 1 | N23: 1 | O23: 46156 | S23: 46158 | U23: 46162 | W23: 46163 | X23: 46164 | Z23: 46190 | AA23: 2026 | AB23: Jack | AC23: Rapid River | AD23: =IF(COUNT(O23:Z23)>0,1,0) -> 1 | AE23: =IF(COUNT(O23:T23)>0,1,0) -> 1 | AF23: =IF(COUNT(S23:Z23)>0,1,0) -> 1 | AG23: =IF(COUNT(S23:T23)>0,1,0) -> 1 | AH23: =IF(COUNT(U23:Z23)>0,1,0) -> 1 | AI23: =IF(COUNT(U23:V23)>0,1,0) -> 1 | AJ23: =IF(COUNT(W23:Z23)>0,1,0) -> 1 | AK23: =IF(COUNT(W23)>0,1,0) -> 1 | AL23: =IF(COUNT(X23:Z23)>0,1,0) -> 1 | AM23: =IF(COUNT(X23)>0,1,0) -> 1 | AN23: =IF(COUNT(Y23:Z23)>0,1,0) -> 1 | AO23: =IF(COUNT(Y23)>0,1,0) -> 0 | AP23: =IF(COUNT(Z23)>0,1,0) -> 1 | AQ23: =IF(AE23+AI23>1,1,0) -> 1 | AR23: =IF(AE23+AK23>1,1,0) -> 1 | AS23: =IF(AP23+AE23>1,1,0) -> 1 | AT23: =IF(AQ23=1,MIN(U23:V23)-MIN(O23:T23),"na") -> 6 | AU23: =IF(AR23=1,MAX(W23)-MIN(O23:T23),"na") -> 7 | AV23: =IF(AS23=1,+Z23-MIN(O23:T23),"na") -> 34 | AW23: =IF(AE23>0,DATE(1900,MONTH(MIN(O23:T23)),DAY(MIN(O23:T23))),"na") -> 135 | AX23: =IF(AG23>0,DATE(1900,MONTH(MIN(S23:T23)),DAY(MIN(S23:T23))),"na") -> 137 | AY23: =IF(AI23>0,DATE(1900,MONTH(MIN(U23:V23)),DAY(MIN(U23:V23))),"na") -> 141 | AZ23: =IF(AK23>0,DATE(1900,MONTH(MIN(W23)),DAY(MIN(W23))),"na") -> 142 | BA23: =IF(AM23>0,DATE(1900,MONTH(MIN(X23)),DAY(MIN(X23))),"na") -> 143 | BB23: =IF(AO23>0,DATE(1900,MONTH(MIN(Y23)),DAY(MIN(Y23))),"na") -> na | BC23: =IF(AP23>0,DATE(1900,MONTH(Z23),DAY(Z23)),"na") -> 169 | BD23: =IF(BD$1-$AW23>$CK$1,1,0) -> 0 | BE23: =IF(BE$1-$AW23>$CK$1,1,0) -> 0 | BF23: =IF(BF$1-$AW23>$CK$1,1,0) -> 0 | BG23: =IF(BG$1-$AW23>$CK$1,1,0) -> 0 | BH23: =IF(BH$1-$AW23>$CK$1,1,0) -> 0 | BI23: =IF(BI$1-$AW23>$CK$1,1,0) -> 0 | BJ23: =IF(BJ$1-$AW23>$CK$1,1,0) -> 0 | BK23: =IF(BK$1-$AW23>$CK$1,1,0) -> 0 | ... BR23: =IF(BR$1-$AW23>$CK$1,1,0) -> 1 | BS23: =IF(AND(BD23=1,$AP23=1),1,0) -> 0 | BT23: =IF(AND(BE23=1,$AP23=1),1,0) -> 0 | BU23: =IF(AND(BF23=1,$AP23=1),1,0) -> 0 | BV23: =IF(AND(BG23=1,$AP23=1),1,0) -> 0 | BW23: =IF(AND(BH23=1,$AP23=1),1,0) -> 0 | BX23: =IF(AND(BI23=1,$AP23=1),1,0) -> 0 | BY23: =IF(AND(BJ23=1,$AP23=1),1,0) -> 0 | BZ23: =IF(AND(BK23=1,$AP23=1),1,0) -> 0 | ... CG23: =IF(AND(BR23=1,$AP23=1),1,0) -> 1
A24: 3DD.003E3489EC | B24: 12H | C24: 2023 | D24: 2025 | E24: McCall Hatchery | F24: SF SALMON | G24: KNOXB - Knox Bridge, SF Salmon River | H24: KNOXB | I24: AI CW | L24: RAL | M24: 7.74 | N24: 1 | O24: 46185 | S24: 46186 | U24: 46189 | W24: 46191 | X24: 46192 | Y24: 46194 | Z24: 46195 | AA24: 2026 | AB24: Jack | AC24: McCall-Integrated | AD24: =IF(COUNT(O24:Z24)>0,1,0) -> 1 | AE24: =IF(COUNT(O24:T24)>0,1,0) -> 1 | AF24: =IF(COUNT(S24:Z24)>0,1,0) -> 1 | AG24: =IF(COUNT(S24:T24)>0,1,0) -> 1 | AH24: =IF(COUNT(U24:Z24)>0,1,0) -> 1 | AI24: =IF(COUNT(U24:V24)>0,1,0) -> 1 | AJ24: =IF(COUNT(W24:Z24)>0,1,0) -> 1 | AK24: =IF(COUNT(W24)>0,1,0) -> 1 | AL24: =IF(COUNT(X24:Z24)>0,1,0) -> 1 | AM24: =IF(COUNT(X24)>0,1,0) -> 1 | AN24: =IF(COUNT(Y24:Z24)>0,1,0) -> 1 | AO24: =IF(COUNT(Y24)>0,1,0) -> 1 | AP24: =IF(COUNT(Z24)>0,1,0) -> 1 | AQ24: =IF(AE24+AI24>1,1,0) -> 1 | AR24: =IF(AE24+AK24>1,1,0) -> 1 | AS24: =IF(AP24+AE24>1,1,0) -> 1 | AT24: =IF(AQ24=1,MIN(U24:V24)-MIN(O24:T24),"na") -> 4 | AU24: =IF(AR24=1,MAX(W24)-MIN(O24:T24),"na") -> 6 | AV24: =IF(AS24=1,+Z24-MIN(O24:T24),"na") -> 10 | AW24: =IF(AE24>0,DATE(1900,MONTH(MIN(O24:T24)),DAY(MIN(O24:T24))),"na") -> 164 | AX24: =IF(AG24>0,DATE(1900,MONTH(MIN(S24:T24)),DAY(MIN(S24:T24))),"na") -> 165 | AY24: =IF(AI24>0,DATE(1900,MONTH(MIN(U24:V24)),DAY(MIN(U24:V24))),"na") -> 168 | AZ24: =IF(AK24>0,DATE(1900,MONTH(MIN(W24)),DAY(MIN(W24))),"na") -> 170 | BA24: =IF(AM24>0,DATE(1900,MONTH(MIN(X24)),DAY(MIN(X24))),"na") -> 171 | BB24: =IF(AO24>0,DATE(1900,MONTH(MIN(Y24)),DAY(MIN(Y24))),"na") -> 173 | BC24: =IF(AP24>0,DATE(1900,MONTH(Z24),DAY(Z24)),"na") -> 174 | BD24: =IF(BD$1-$AW24>$CK$1,1,0) -> 0 | BE24: =IF(BE$1-$AW24>$CK$1,1,0) -> 0 | BF24: =IF(BF$1-$AW24>$CK$1,1,0) -> 0 | BG24: =IF(BG$1-$AW24>$CK$1,1,0) -> 0 | BH24: =IF(BH$1-$AW24>$CK$1,1,0) -> 0 | BI24: =IF(BI$1-$AW24>$CK$1,1,0) -> 0 | BJ24: =IF(BJ$1-$AW24>$CK$1,1,0) -> 0 | BK24: =IF(BK$1-$AW24>$CK$1,1,0) -> 0 | ... BR24: =IF(BR$1-$AW24>$CK$1,1,0) -> 1 | BS24: =IF(AND(BD24=1,$AP24=1),1,0) -> 0 | BT24: =IF(AND(BE24=1,$AP24=1),1,0) -> 0 | BU24: =IF(AND(BF24=1,$AP24=1),1,0) -> 0 | BV24: =IF(AND(BG24=1,$AP24=1),1,0) -> 0 | BW24: =IF(AND(BH24=1,$AP24=1),1,0) -> 0 | BX24: =IF(AND(BI24=1,$AP24=1),1,0) -> 0 | BY24: =IF(AND(BJ24=1,$AP24=1),1,0) -> 0 | BZ24: =IF(AND(BK24=1,$AP24=1),1,0) -> 0 | ... CG24: =IF(AND(BR24=1,$AP24=1),1,0) -> 1
A25: 3DD.003E53CBC6 | B25: 11H | C25: 2023 | D25: 2025 | E25: Rapid River Hatchery | F25: RAPID RIVER | G25: RAPH - Rapid River Hatchery | H25: RAPH | I25: AD | L25: RAL | M25: 74.25 | N25: 1 | Q25: 46145 | R25: 46145 | S25: 46148 | U25: 46151 | W25: 46152 | X25: 46153 | Y25: 46154 | Z25: 46155 | AA25: 2026 | AB25: Jack | AC25: Rapid River | AD25: =IF(COUNT(O25:Z25)>0,1,0) -> 1 | AE25: =IF(COUNT(O25:T25)>0,1,0) -> 1 | AF25: =IF(COUNT(S25:Z25)>0,1,0) -> 1 | AG25: =IF(COUNT(S25:T25)>0,1,0) -> 1 | AH25: =IF(COUNT(U25:Z25)>0,1,0) -> 1 | AI25: =IF(COUNT(U25:V25)>0,1,0) -> 1 | AJ25: =IF(COUNT(W25:Z25)>0,1,0) -> 1 | AK25: =IF(COUNT(W25)>0,1,0) -> 1 | AL25: =IF(COUNT(X25:Z25)>0,1,0) -> 1 | AM25: =IF(COUNT(X25)>0,1,0) -> 1 | AN25: =IF(COUNT(Y25:Z25)>0,1,0) -> 1 | AO25: =IF(COUNT(Y25)>0,1,0) -> 1 | AP25: =IF(COUNT(Z25)>0,1,0) -> 1 | AQ25: =IF(AE25+AI25>1,1,0) -> 1 | AR25: =IF(AE25+AK25>1,1,0) -> 1 | AS25: =IF(AP25+AE25>1,1,0) -> 1 | AT25: =IF(AQ25=1,MIN(U25:V25)-MIN(O25:T25),"na") -> 6 | AU25: =IF(AR25=1,MAX(W25)-MIN(O25:T25),"na") -> 7 | AV25: =IF(AS25=1,+Z25-MIN(O25:T25),"na") -> 10 | AW25: =IF(AE25>0,DATE(1900,MONTH(MIN(O25:T25)),DAY(MIN(O25:T25))),"na") -> 124 | AX25: =IF(AG25>0,DATE(1900,MONTH(MIN(S25:T25)),DAY(MIN(S25:T25))),"na") -> 127 | AY25: =IF(AI25>0,DATE(1900,MONTH(MIN(U25:V25)),DAY(MIN(U25:V25))),"na") -> 130 | AZ25: =IF(AK25>0,DATE(1900,MONTH(MIN(W25)),DAY(MIN(W25))),"na") -> 131 | BA25: =IF(AM25>0,DATE(1900,MONTH(MIN(X25)),DAY(MIN(X25))),"na") -> 132 | BB25: =IF(AO25>0,DATE(1900,MONTH(MIN(Y25)),DAY(MIN(Y25))),"na") -> 133 | BC25: =IF(AP25>0,DATE(1900,MONTH(Z25),DAY(Z25)),"na") -> 134 | BD25: =IF(BD$1-$AW25>$CK$1,1,0) -> 0 | BE25: =IF(BE$1-$AW25>$CK$1,1,0) -> 0 | BF25: =IF(BF$1-$AW25>$CK$1,1,0) -> 0 | BG25: =IF(BG$1-$AW25>$CK$1,1,0) -> 0 | BH25: =IF(BH$1-$AW25>$CK$1,1,0) -> 0 | BI25: =IF(BI$1-$AW25>$CK$1,1,0) -> 0 | BJ25: =IF(BJ$1-$AW25>$CK$1,1,0) -> 0 | BK25: =IF(BK$1-$AW25>$CK$1,1,0) -> 0 | ... BR25: =IF(BR$1-$AW25>$CK$1,1,0) -> 1 | BS25: =IF(AND(BD25=1,$AP25=1),1,0) -> 0 | BT25: =IF(AND(BE25=1,$AP25=1),1,0) -> 0 | BU25: =IF(AND(BF25=1,$AP25=1),1,0) -> 0 | BV25: =IF(AND(BG25=1,$AP25=1),1,0) -> 0 | BW25: =IF(AND(BH25=1,$AP25=1),1,0) -> 0 | BX25: =IF(AND(BI25=1,$AP25=1),1,0) -> 0 | BY25: =IF(AND(BJ25=1,$AP25=1),1,0) -> 0 | BZ25: =IF(AND(BK25=1,$AP25=1),1,0) -> 0 | ... CG25: =IF(AND(BR25=1,$AP25=1),1,0) -> 1
A26: 3DD.003E339440 | B26: 12H | C26: 2023 | D26: 2025 | E26: McCall Hatchery | F26: SF SALMON | G26: KNOXB - Knox Bridge, SF Salmon River | H26: KNOXB | I26: AD | L26: RAL | M26: 50.77 | N26: 1 | Q26: 46173 | R26: 46173 | T26: 46175 | W26: 46180 | X26: 46181 | Y26: 46182 | Z26: 46184 | AA26: 2026 | AB26: Jack | AC26: McCall-Segregated | AD26: =IF(COUNT(O26:Z26)>0,1,0) -> 1 | AE26: =IF(COUNT(O26:T26)>0,1,0) -> 1 | AF26: =IF(COUNT(S26:Z26)>0,1,0) -> 1 | AG26: =IF(COUNT(S26:T26)>0,1,0) -> 1 | AH26: =IF(COUNT(U26:Z26)>0,1,0) -> 1 | AI26: =IF(COUNT(U26:V26)>0,1,0) -> 0 | AJ26: =IF(COUNT(W26:Z26)>0,1,0) -> 1 | AK26: =IF(COUNT(W26)>0,1,0) -> 1 | AL26: =IF(COUNT(X26:Z26)>0,1,0) -> 1 | AM26: =IF(COUNT(X26)>0,1,0) -> 1 | AN26: =IF(COUNT(Y26:Z26)>0,1,0) -> 1 | AO26: =IF(COUNT(Y26)>0,1,0) -> 1 | AP26: =IF(COUNT(Z26)>0,1,0) -> 1 | AQ26: =IF(AE26+AI26>1,1,0) -> 0 | AR26: =IF(AE26+AK26>1,1,0) -> 1 | AS26: =IF(AP26+AE26>1,1,0) -> 1 | AT26: =IF(AQ26=1,MIN(U26:V26)-MIN(O26:T26),"na") -> na | AU26: =IF(AR26=1,MAX(W26)-MIN(O26:T26),"na") -> 7 | AV26: =IF(AS26=1,+Z26-MIN(O26:T26),"na") -> 11 | AW26: =IF(AE26>0,DATE(1900,MONTH(MIN(O26:T26)),DAY(MIN(O26:T26))),"na") -> 152 | AX26: =IF(AG26>0,DATE(1900,MONTH(MIN(S26:T26)),DAY(MIN(S26:T26))),"na") -> 154 | AY26: =IF(AI26>0,DATE(1900,MONTH(MIN(U26:V26)),DAY(MIN(U26:V26))),"na") -> na | AZ26: =IF(AK26>0,DATE(1900,MONTH(MIN(W26)),DAY(MIN(W26))),"na") -> 159 | BA26: =IF(AM26>0,DATE(1900,MONTH(MIN(X26)),DAY(MIN(X26))),"na") -> 160 | BB26: =IF(AO26>0,DATE(1900,MONTH(MIN(Y26)),DAY(MIN(Y26))),"na") -> 161 | BC26: =IF(AP26>0,DATE(1900,MONTH(Z26),DAY(Z26)),"na") -> 163 | BD26: =IF(BD$1-$AW26>$CK$1,1,0) -> 0 | BE26: =IF(BE$1-$AW26>$CK$1,1,0) -> 0 | BF26: =IF(BF$1-$AW26>$CK$1,1,0) -> 0 | BG26: =IF(BG$1-$AW26>$CK$1,1,0) -> 0 | BH26: =IF(BH$1-$AW26>$CK$1,1,0) -> 0 | BI26: =IF(BI$1-$AW26>$CK$1,1,0) -> 0 | BJ26: =IF(BJ$1-$AW26>$CK$1,1,0) -> 0 | BK26: =IF(BK$1-$AW26>$CK$1,1,0) -> 0 | ... BR26: =IF(BR$1-$AW26>$CK$1,1,0) -> 1 | BS26: =IF(AND(BD26=1,$AP26=1),1,0) -> 0 | BT26: =IF(AND(BE26=1,$AP26=1),1,0) -> 0 | BU26: =IF(AND(BF26=1,$AP26=1),1,0) -> 0 | BV26: =IF(AND(BG26=1,$AP26=1),1,0) -> 0 | BW26: =IF(AND(BH26=1,$AP26=1),1,0) -> 0 | BX26: =IF(AND(BI26=1,$AP26=1),1,0) -> 0 | BY26: =IF(AND(BJ26=1,$AP26=1),1,0) -> 0 | BZ26: =IF(AND(BK26=1,$AP26=1),1,0) -> 0 | ... CG26: =IF(AND(BR26=1,$AP26=1),1,0) -> 1
